<?xml version="1.0" encoding="utf-8"?>

<robot name="thorvald_ii" xmlns:xacro="http://www.ros.org/wiki/xacro">

  <xacro:include filename="$(find realsense_t265)/urdf/_t265.urdf.xacro"/>

  <gazebo>
    <plugin filename="libthorvald_gazebo_plugins_synch.so" name="_thorvald_gazebo_plugins">
      <alwaysOn>true</alwaysOn>
      <updateRate>20</updateRate>
      <robotNamespace></robotNamespace>
      <commandTopic>base_state</commandTopic>
      <odometryTopic>odometry/gazebo</odometryTopic>
      <odometryFrame>odom</odometryFrame>
      <robotBaseFrame>base_link</robotBaseFrame>
      <steering0>steering0</steering0>
      <steering1>steering1</steering1>
      <steering2>steering2</steering2>
      <steering3>steering3</steering3>
      <steering4>steering4</steering4>
      <steering5>steering5</steering5>
      <steering6>steering6</steering6>
      <steering7>steering7</steering7>
      <steering8>steering8</steering8>
      <steering9>steering9</steering9>
      <steering10>ssteering10</steering10>
      <wheel0>wheel0</wheel0>
      <wheel1>wheel1</wheel1>
      <wheel2>wheel2</wheel2>
      <wheel3>wheel3</wheel3>
      <wheel4>wheel4</wheel4>
      <wheel5>wheel5</wheel5>
      <wheel6>wheel6</wheel6>
      <wheel7>wheel7</wheel7>
      <wheel8>wheel8</wheel8>
      <wheel9>wheel9</wheel9>
      <wheel10>wheel10</wheel10>
    </plugin>
  </gazebo>
  <!--
    <alwaysOn>true</alwaysOn>
    <robotNamespace>thorvald_ii</robotNamespace>
    <steering2>steering2</steering2>
    <steering1>steering1</steering1>
    <steering3>steering3</steering3>
    <steering0>steering0</steering0>
    <publishOdometryMsg>true</publishOdometryMsg>
    <publishOdometryTf>true</publishOdometryTf>
    <robotBaseFrame>base_link</robotBaseFrame>
    <commandTopic>joint_commands</commandTopic>
    <odometryTopic>odom</odometryTopic>
    <odometryFrame>odom</odometryFrame>
    <updateRate>100.0</updateRate>
    <platform_width>0.570</platform_width>
    <wheel_radius>0.400</wheel_radius>
      <torque>5.0</torque>
    </plugin>
  </gazebo> -->


  <!-- MATERIAL DEFINITIONS -->
  <material name="white">
    <color rgba="1 1 1 1"/>
  </material>
  <material name="black">
    <color rgba="0 0 0 1"/>
  </material>
  <material name="red">
    <color rgba="1 0 0 1"/>
  </material>
  <material name="green">
    <color rgba="0 1 0 1"/>
  </material>
  <material name="alu">
    <color rgba="0.75 0.75 0.75 1"/>
  </material>


  <!-- CREATE ROBOT -->
  <!-- Create base link -->
  <link name="base_link"/>
  <link name="top0">
    <inertial>
      <mass value="10.21"/>
      <origin rpy="0 0 0" xyz="0 0 0"/>
      <inertia ixx="0.187252250833" ixy="0.0" ixz="0.0" iyy="0.209836770833" iyz="0.0" izz="0.119499541667"/>
    </inertial>
    <visual>
      <geometry>
        <mesh filename="package://thorvald_description/meshes/tower_modules/DUMMY-TOWER-M.stl"/>
        <box size="0.265 0.209 0.42"/>
      </geometry>
      <material name="white"/>
    </visual>
    <collision>
      <geometry>
        <mesh filename="package://thorvald_description/meshes/tower_modules/DUMMY-TOWER-M.stl"/>
        <box size="0.265 0.209 0.42"/>
      </geometry>
    </collision>
  </link>
  <joint name="base_linktop0" type="fixed">
    <parent link="base_link"/>
    <child link="top0"/>
    <origin rpy="0 0 3.14159265359" xyz="-0.67792 -0.75 0.65"/>
    <axis xyz="0 0 1"/>
  </joint>


  <link name="leg0">
    <inertial>
      <mass value="15.64"/>
      <origin rpy="0 0 0" xyz="0 0 0"/>
      <inertia ixx="0.035581" ixy="0.0" ixz="0.0" iyy="0.035581" iyz="0.0" izz="0.012512"/>
    </inertial>
    <visual>
      <origin rpy="0 0 3.14159265359" xyz="0 0 0"/>
      <geometry>
        <mesh filename="package://thorvald_description/meshes/drive_modules/836745-5-DUMMY-RevA.stl"/>
        <cylinder length="-0.15" radius="0.04"/>
        <!--mesh filename="package://thorvald_base/meshes/top_chassis.dae"/-->
      </geometry>
      <material name="white"/>
    </visual>
    <collision>
      <origin rpy="0 0 3.14159265359" xyz="0 0 0"/>
      <geometry>
        <mesh filename="package://thorvald_description/meshes/drive_modules/836745-5-DUMMY-RevA.stl"/>
        <cylinder length="-0.15" radius="0.04"/>
      </geometry>
    </collision>
  </link>
  <joint name="steering0" type="continuous">
    <parent link="base_link"/>
    <child link="leg0"/>
    <origin rpy="0 0 0" xyz="-0.67792 -0.75 0.2"/>
    <axis xyz="0 0 1"/>
    <dynamics damping="100" friction="10000"/>
  </joint>
  <transmission name="steering0_tran">
    <type>transmission_interface/SimpleTransmission</type>
    <joint name="steering0">
      <hardwareInterface>hardware_interface/EffortJointInterface</hardwareInterface>
    </joint>
    <actuator name="steering0_motor">
      <hardwareInterface>hardware_interface/EffortJointInterface</hardwareInterface>
      <mechanicalReduction>1</mechanicalReduction>
    </actuator>
  </transmission>

  
  <link name="wheel0_link">
    <inertial>
      <mass value="6.0"/>
      <origin rpy="0 0 0" xyz="0 0 0"/>
      <inertia ixx="0.0728" ixy="0.0" ixz="0.0" iyy="0.0728" iyz="0.0" izz="0.12"/>
    </inertial>
    <visual>
      <geometry>
        <cylinder length="0.16" radius="0.2"/>
        <!-- <box size = "0.00001 0.00001 0.00001"/> -->
      </geometry>
      <material name="black"/>
    </visual>
    <collision>
      <geometry>
        <cylinder length="0.16" radius="0.2"/>
        <!-- <box size = "0.00001 0.00001 0.00001"/> -->
      </geometry>
    </collision>
  </link>
  <gazebo reference="wheel0_link">
    <material>Gazebo/Black</material>
    <mu1 value="2"/>
    <mu2 value="2"/>
  </gazebo>
  <joint name="wheel0" type="continuous">
    <parent link="leg0"/>
    <child link="wheel0_link"/>
    <origin rpy="-1.57079632679 0 0" xyz="0 0 0"/>
    <axis xyz="0 0 1"/>
    <dynamics damping="100" friction="1000"/>
  </joint>
  <transmission name="wheel0_tran">
    <type>transmission_interface/SimpleTransmission</type>
    <joint name="wheel0">
      <hardwareInterface>hardware_interface/EffortJointInterface</hardwareInterface>
    </joint>
    <actuator name="wheel0_motor">
      <hardwareInterface>hardware_interface/EffortJointInterface</hardwareInterface>
      <mechanicalReduction>1</mechanicalReduction>
    </actuator>
  </transmission>
  
  <link name="top1">
    <inertial>
      <mass value="10.21"/>
      <origin rpy="0 0 0" xyz="0 0 0"/>
      <inertia ixx="0.187252250833" ixy="0.0" ixz="0.0" iyy="0.209836770833" iyz="0.0" izz="0.119499541667"/>
    </inertial>
    <visual>
      <geometry>
        <mesh filename="package://thorvald_description/meshes/tower_modules/DUMMY-TOWER-MIRROR-M.stl"/>
        <box size="0.265 0.209 0.42"/>
      </geometry>
      <material name="white"/>
    </visual>
    <collision>
      <geometry>
        <mesh filename="package://thorvald_description/meshes/tower_modules/DUMMY-TOWER-MIRROR-M.stl"/>
        <box size="0.265 0.209 0.42"/>
      </geometry>
    </collision>
  </link>
  <joint name="base_linktop1" type="fixed">
    <parent link="base_link"/>
    <child link="top1"/>
    <origin rpy="0 0 0" xyz="0.67792 -0.75 0.65"/>
    <axis xyz="0 0 1"/>
  </joint>


  <link name="leg1">
    <inertial>
      <mass value="15.64"/>
      <origin rpy="0 0 0" xyz="0 0 0"/>
      <inertia ixx="0.035581" ixy="0.0" ixz="0.0" iyy="0.035581" iyz="0.0" izz="0.012512"/>
    </inertial>
    <visual>
      <origin rpy="0 0 0" xyz="0 0 0"/>
      <geometry>
        <mesh filename="package://thorvald_description/meshes/drive_modules/836745-5-DUMMY-MIRROR-RevA.stl"/>
        <cylinder length="-0.15" radius="0.04"/>
        <!--mesh filename="package://thorvald_base/meshes/top_chassis.dae"/-->
      </geometry>
      <material name="white"/>
    </visual>
    <collision>
      <origin rpy="0 0 0" xyz="0 0 0"/>
      <geometry>
        <mesh filename="package://thorvald_description/meshes/drive_modules/836745-5-DUMMY-MIRROR-RevA.stl"/>
        <cylinder length="-0.15" radius="0.04"/>
      </geometry>
    </collision>
  </link>
  <joint name="steering1" type="continuous">
    <parent link="base_link"/>
    <child link="leg1"/>
    <origin rpy="0 0 0" xyz="0.67792 -0.75 0.2"/>
    <axis xyz="0 0 1"/>
    <dynamics damping="100" friction="10000"/>
  </joint>
  <transmission name="steering1_tran">
    <type>transmission_interface/SimpleTransmission</type>
    <joint name="steering1">
      <hardwareInterface>hardware_interface/EffortJointInterface</hardwareInterface>
    </joint>
    <actuator name="steering1_motor">
      <hardwareInterface>hardware_interface/EffortJointInterface</hardwareInterface>
      <mechanicalReduction>1</mechanicalReduction>
    </actuator>
  </transmission>


  <link name="wheel1_link">
    <inertial>
      <mass value="6.0"/>
      <origin rpy="0 0 0" xyz="0 0 0"/>
      <inertia ixx="0.0728" ixy="0.0" ixz="0.0" iyy="0.0728" iyz="0.0" izz="0.12"/>
    </inertial>
    <visual>
      <geometry>
        <cylinder length="0.16" radius="0.2"/>
        <!-- <box size = "0.00001 0.00001 0.00001"/> -->
      </geometry>
      <material name="black"/>
    </visual>
    <collision>
      <geometry>
        <cylinder length="0.16" radius="0.2"/>
        <!-- <box size = "0.00001 0.00001 0.00001"/> -->
      </geometry>
    </collision>
  </link>
  <gazebo reference="wheel1_link">
    <material>Gazebo/Black</material>
    <mu1 value="2"/>
    <mu2 value="2"/>
  </gazebo>
  <joint name="wheel1" type="continuous">
    <parent link="leg1"/>
    <child link="wheel1_link"/>
    <origin rpy="-1.57079632679 0 0" xyz="0 0 0"/>
    <axis xyz="0 0 1"/>
    <dynamics damping="100" friction="1000"/>
  </joint>
  <transmission name="wheel1_tran">
    <type>transmission_interface/SimpleTransmission</type>
    <joint name="wheel1">
      <hardwareInterface>hardware_interface/EffortJointInterface</hardwareInterface>
    </joint>
    <actuator name="wheel1_motor">
      <hardwareInterface>hardware_interface/EffortJointInterface</hardwareInterface>
      <mechanicalReduction>1</mechanicalReduction>
    </actuator>
  </transmission>
   
  <link name="top2">
    <inertial>
      <mass value="10.21"/>
      <origin rpy="0 0 0" xyz="0 0 0"/>
      <inertia ixx="0.187252250833" ixy="0.0" ixz="0.0" iyy="0.209836770833" iyz="0.0" izz="0.119499541667"/>
    </inertial>
    <visual>
      <geometry>
        <mesh filename="package://thorvald_description/meshes/tower_modules/DUMMY-TOWER-M.stl"/>
        <box size="0.265 0.209 0.42"/>
      </geometry>
      <material name="white"/>
    </visual>
    <collision>
      <geometry>
        <mesh filename="package://thorvald_description/meshes/tower_modules/DUMMY-TOWER-M.stl"/>
        <box size="0.265 0.209 0.42"/>
      </geometry>
    </collision>
  </link>
  <joint name="base_linktop2" type="fixed">
    <parent link="base_link"/>
    <child link="top2"/>
    <origin rpy="0 0 0" xyz="0.67792 0.75 0.65"/>
    <axis xyz="0 0 1"/>
  </joint>


  <link name="leg2">
    <inertial>
      <mass value="15.64"/>
      <origin rpy="0 0 0" xyz="0 0 0"/>
      <inertia ixx="0.035581" ixy="0.0" ixz="0.0" iyy="0.035581" iyz="0.0" izz="0.012512"/>
    </inertial>
    <visual>
      <origin rpy="0 0 0" xyz="0 0 0"/>
      <geometry>
        <mesh filename="package://thorvald_description/meshes/drive_modules/836745-5-DUMMY-RevA.stl"/>
        <cylinder length="-0.15" radius="0.04"/>
        <!--mesh filename="package://thorvald_base/meshes/top_chassis.dae"/-->
      </geometry>
      <material name="white"/>
    </visual>
    <collision>
      <origin rpy="0 0 0" xyz="0 0 0"/>
      <geometry>
        <mesh filename="package://thorvald_description/meshes/drive_modules/836745-5-DUMMY-RevA.stl"/>
        <cylinder length="-0.15" radius="0.04"/>
      </geometry>
    </collision>
  </link>
  <joint name="steering2" type="continuous">
    <parent link="base_link"/>
    <child link="leg2"/>
    <origin rpy="0 0 0" xyz="0.67792 0.75 0.2"/>
    <axis xyz="0 0 1"/>
    <dynamics damping="100" friction="10000"/>
  </joint>
  <transmission name="steering2_tran">
    <type>transmission_interface/SimpleTransmission</type>
    <joint name="steering2">
      <hardwareInterface>hardware_interface/EffortJointInterface</hardwareInterface>
    </joint>
    <actuator name="steering2_motor">
      <hardwareInterface>hardware_interface/EffortJointInterface</hardwareInterface>
      <mechanicalReduction>1</mechanicalReduction>
    </actuator>
  </transmission>


  <link name="wheel2_link">
    <inertial>
      <mass value="6.0"/>
      <origin rpy="0 0 0" xyz="0 0 0"/>
      <inertia ixx="0.0728" ixy="0.0" ixz="0.0" iyy="0.0728" iyz="0.0" izz="0.12"/>
    </inertial>
    <visual>
      <geometry>
        <cylinder length="0.16" radius="0.2"/>
        <!-- <box size = "0.00001 0.00001 0.00001"/> -->
      </geometry>
      <material name="black"/>
    </visual>
    <collision>
      <geometry>
        <cylinder length="0.16" radius="0.2"/>
        <!-- <box size = "0.00001 0.00001 0.00001"/> -->
      </geometry>
    </collision>
  </link>
  <gazebo reference="wheel2_link">
    <material>Gazebo/Black</material>
    <mu1 value="2"/>
    <mu2 value="2"/>
  </gazebo>
  <joint name="wheel2" type="continuous">
    <parent link="leg2"/>
    <child link="wheel2_link"/>
    <origin rpy="-1.57079632679 0 0" xyz="0 0 0"/>
    <axis xyz="0 0 1"/>
    <dynamics damping="100" friction="1000"/>
  </joint>
  <transmission name="wheel2_tran">
    <type>transmission_interface/SimpleTransmission</type>
    <joint name="wheel2">
      <hardwareInterface>hardware_interface/EffortJointInterface</hardwareInterface>
    </joint>
    <actuator name="wheel2_motor">
      <hardwareInterface>hardware_interface/EffortJointInterface</hardwareInterface>
      <mechanicalReduction>1</mechanicalReduction>
    </actuator>
  </transmission>
  
  <link name="top3">
    <inertial>
      <mass value="10.21"/>
      <origin rpy="0 0 0" xyz="0 0 0"/>
      <inertia ixx="0.187252250833" ixy="0.0" ixz="0.0" iyy="0.209836770833" iyz="0.0" izz="0.119499541667"/>
    </inertial>
    <visual>
      <geometry>
        <mesh filename="package://thorvald_description/meshes/tower_modules/DUMMY-TOWER-MIRROR-M.stl"/>
        <box size="0.265 0.209 0.42"/>
      </geometry>
      <material name="white"/>
    </visual>
    <collision>
      <geometry>
        <mesh filename="package://thorvald_description/meshes/tower_modules/DUMMY-TOWER-MIRROR-M.stl"/>
        <box size="0.265 0.209 0.42"/>
      </geometry>
    </collision>
  </link>
  <joint name="base_linktop3" type="fixed">
    <parent link="base_link"/>
    <child link="top3"/>
    <origin rpy="0 0 3.14159265359" xyz="-0.67792 0.75 0.65"/>
    <axis xyz="0 0 1"/>
  </joint>


  <link name="leg3">
    <inertial>
      <mass value="15.64"/>
      <origin rpy="0 0 0" xyz="0 0 0"/>
      <inertia ixx="0.035581" ixy="0.0" ixz="0.0" iyy="0.035581" iyz="0.0" izz="0.012512"/>
    </inertial>
    <visual>
      <origin rpy="0 0 3.14159265359" xyz="0 0 0"/>
      <geometry>
        <mesh filename="package://thorvald_description/meshes/drive_modules/836745-5-DUMMY-MIRROR-RevA.stl"/>
        <cylinder length="-0.15" radius="0.04"/>
        <!--mesh filename="package://thorvald_base/meshes/top_chassis.dae"/-->
      </geometry>
      <material name="white"/>
    </visual>
    <collision>
      <origin rpy="0 0 3.14159265359" xyz="0 0 0"/>
      <geometry>
        <mesh filename="package://thorvald_description/meshes/drive_modules/836745-5-DUMMY-MIRROR-RevA.stl"/>
        <cylinder length="-0.15" radius="0.04"/>
      </geometry>
    </collision>
  </link>
  <joint name="steering3" type="continuous">
    <parent link="base_link"/>
    <child link="leg3"/>
    <origin rpy="0 0 0" xyz="-0.67792 0.75 0.2"/>
    <axis xyz="0 0 1"/>
    <dynamics damping="100" friction="10000"/>
  </joint>
  <transmission name="steering3_tran">
    <type>transmission_interface/SimpleTransmission</type>
    <joint name="steering3">
      <hardwareInterface>hardware_interface/EffortJointInterface</hardwareInterface>
    </joint>
    <actuator name="steering3_motor">
      <hardwareInterface>hardware_interface/EffortJointInterface</hardwareInterface>
      <mechanicalReduction>1</mechanicalReduction>
    </actuator>
  </transmission>


  <link name="wheel3_link">
    <inertial>
      <mass value="6.0"/>
      <origin rpy="0 0 0" xyz="0 0 0"/>
      <inertia ixx="0.0728" ixy="0.0" ixz="0.0" iyy="0.0728" iyz="0.0" izz="0.12"/>
    </inertial>
    <visual>
      <geometry>
        <cylinder length="0.16" radius="0.2"/>
        <!-- <box size = "0.00001 0.00001 0.00001"/> -->
      </geometry>
      <material name="black"/>
    </visual>
    <collision>
      <geometry>
        <cylinder length="0.16" radius="0.2"/>
        <!-- <box size = "0.00001 0.00001 0.00001"/> -->
      </geometry>
    </collision>
  </link>
  <gazebo reference="wheel3_link">
    <material>Gazebo/Black</material>
    <mu1 value="2"/>
    <mu2 value="2"/>
  </gazebo>
  <joint name="wheel3" type="continuous">
    <parent link="leg3"/>
    <child link="wheel3_link"/>
    <origin rpy="-1.57079632679 0 0" xyz="0 0 0"/>
    <axis xyz="0 0 1"/>
    <dynamics damping="100" friction="1000"/>
  </joint>
  <transmission name="wheel3_tran">
    <type>transmission_interface/SimpleTransmission</type>
    <joint name="wheel3">
      <hardwareInterface>hardware_interface/EffortJointInterface</hardwareInterface>
    </joint>
    <actuator name="wheel3_motor">
      <hardwareInterface>hardware_interface/EffortJointInterface</hardwareInterface>
      <mechanicalReduction>1</mechanicalReduction>
    </actuator>
  </transmission>
   
  <link name="corner0_1">
    <inertial>
      <mass value="0.915"/>
      <origin rpy="0 0 0" xyz="0 0 0"/>
      <inertia ixx="0.001282525" ixy="0.0" ixz="0.0" iyy="0.001751005" iyz="0.0" izz="0.002989"/>
    </inertial>
    <visual>
      <geometry>
        <mesh filename="package://thorvald_description/meshes/clamps/DUMMY-T-BRACKET.stl"/>
        <box size="0.140 0.116 0.058"/>
      </geometry>
      <material name="alu"/>
    </visual>
    <collision>
      <geometry>
        <box size="0.140 0.116 0.058"/>
      </geometry>
    </collision>
  </link>


  <link name="corner0_2">
    <inertial>
      <mass value="0.915"/>
      <origin rpy="0 0 0" xyz="0 0 0"/>
      <inertia ixx="0.001282525" ixy="0.0" ixz="0.0" iyy="0.001751005" iyz="0.0" izz="0.002989"/>
    </inertial>
    <visual>
      <geometry>
        <mesh filename="package://thorvald_description/meshes/clamps/DUMMY-T-BRACKET.stl"/>
        <box size="0.140 0.116 0.058"/>
      </geometry>
      <material name="alu"/>
    </visual>
    <collision>
      <geometry>
        <box size="0.140 0.116 0.058"/>
      </geometry>
    </collision>
  </link>


  <link name="corner0">
    <inertial>
      <mass value="0.915"/>
      <origin rpy="0 0 0" xyz="0 0 0"/>
      <inertia ixx="0.001807125" ixy="0.0" ixz="0.0" iyy="0.001807125" iyz="0.0" izz="0.000183"/>
    </inertial>
    <visual>
      <geometry>
        <cylinder length="0.15" radius="0.02"/>
        <!-- <box size = "0.00001 0.00001 0.00001" /> -->
      </geometry>
      <material name="alu"/>
    </visual>
    <collision>
      <geometry>
        <cylinder length="0.15" radius="0.02"/>
      </geometry>
    </collision>
  </link>
  <joint name="corner0_link_1" type="fixed">
    <parent link="corner0"/>
    <child link="corner0_1"/>
    <origin rpy="0 0 0" xyz="0.057 0 -0.075"/>
    <axis xyz="0 0 1"/>
  </joint>
  <joint name="corner0_link_2" type="fixed">
    <parent link="corner0"/>
    <child link="corner0_2"/>
    <origin rpy="0 0 0" xyz="0.057 0 0.075"/>
    <axis xyz="0 0 1"/>
  </joint>


  <link name="corner0_3">
    <inertial>
      <mass value="0.915"/>
      <origin rpy="0 0 0" xyz="0 0 0"/>
      <inertia ixx="0.00149976125" ixy="0.0" ixz="0.0" iyy="0.0018795625" iyz="0.0" izz="0.0036638125"/>
    </inertial>
    <visual>
      <geometry>
        <mesh filename="package://thorvald_description/meshes/clamps/DUMMY-SUSP.stl"/>
        <box size="0.155 0.138 0.025"/>
      </geometry>
      <material name="alu"/>
    </visual>
    <collision>
      <geometry>
        <box size="0.155 0.138 0.025"/>
      </geometry>
    </collision>
  </link>


  <link name="corner0_4">
    <inertial>
      <mass value="0.915"/>
      <origin rpy="0 0 0" xyz="0 0 0"/>
      <inertia ixx="0.00149976125" ixy="0.0" ixz="0.0" iyy="0.0018795625" iyz="0.0" izz="0.0036638125"/>
    </inertial>
    <visual>
      <geometry>
        <mesh filename="package://thorvald_description/meshes/clamps/DUMMY-SUSP.stl"/>
        <box size="0.155 0.138 0.025"/>
      </geometry>
      <material name="alu"/>
    </visual>
    <collision>
      <geometry>
        <box size="0.155 0.138 0.025"/>
      </geometry>
    </collision>
  </link>
  <joint name="corner0_link_3" type="fixed">
    <parent link="corner0"/>
    <child link="corner0_3"/>
    <origin rpy="0 0.25 0" xyz="0.1 0 -0.075"/>
    <axis xyz="0 0 1"/>
  </joint>
  <joint name="corner0_link_4" type="fixed">
    <parent link="corner0"/>
    <child link="corner0_4"/>
    <origin rpy="0 0.25 0" xyz="0.1 0 0.075"/>
    <axis xyz="0 0 1"/>
  </joint>
  <joint name="corner0_link" type="fixed">
    <parent link="base_link"/>
    <child link="corner0"/>
    <origin rpy="0 0 -3.14159265359" xyz="-0.368 -0.75 0.68221"/>
    <axis xyz="0 0 1"/>
  </joint>


  <link name="corner1_1">
    <inertial>
      <mass value="0.915"/>
      <origin rpy="0 0 0" xyz="0 0 0"/>
      <inertia ixx="0.001282525" ixy="0.0" ixz="0.0" iyy="0.001751005" iyz="0.0" izz="0.002989"/>
    </inertial>
    <visual>
      <geometry>
        <mesh filename="package://thorvald_description/meshes/clamps/DUMMY-T-BRACKET.stl"/>
        <box size="0.140 0.116 0.058"/>
      </geometry>
      <material name="alu"/>
    </visual>
    <collision>
      <geometry>
        <box size="0.140 0.116 0.058"/>
      </geometry>
    </collision>
  </link>


  <link name="corner1_2">
    <inertial>
      <mass value="0.915"/>
      <origin rpy="0 0 0" xyz="0 0 0"/>
      <inertia ixx="0.001282525" ixy="0.0" ixz="0.0" iyy="0.001751005" iyz="0.0" izz="0.002989"/>
    </inertial>
    <visual>
      <geometry>
        <mesh filename="package://thorvald_description/meshes/clamps/DUMMY-T-BRACKET.stl"/>
        <box size="0.140 0.116 0.058"/>
      </geometry>
      <material name="alu"/>
    </visual>
    <collision>
      <geometry>
        <box size="0.140 0.116 0.058"/>
      </geometry>
    </collision>
  </link>


  <link name="corner1">
    <inertial>
      <mass value="0.915"/>
      <origin rpy="0 0 0" xyz="0 0 0"/>
      <inertia ixx="0.001807125" ixy="0.0" ixz="0.0" iyy="0.001807125" iyz="0.0" izz="0.000183"/>
    </inertial>
    <visual>
      <geometry>
        <cylinder length="0.15" radius="0.02"/>
        <!-- <box size = "0.00001 0.00001 0.00001" /> -->
      </geometry>
      <material name="alu"/>
    </visual>
    <collision>
      <geometry>
        <cylinder length="0.15" radius="0.02"/>
      </geometry>
    </collision>
  </link>
  <joint name="corner1_link_1" type="fixed">
    <parent link="corner1"/>
    <child link="corner1_1"/>
    <origin rpy="0 0 0" xyz="0.057 0 -0.075"/>
    <axis xyz="0 0 1"/>
  </joint>
  <joint name="corner1_link_2" type="fixed">
    <parent link="corner1"/>
    <child link="corner1_2"/>
    <origin rpy="0 0 0" xyz="0.057 0 0.075"/>
    <axis xyz="0 0 1"/>
  </joint>


  <link name="corner1_3">
    <inertial>
      <mass value="0.915"/>
      <origin rpy="0 0 0" xyz="0 0 0"/>
      <inertia ixx="0.00149976125" ixy="0.0" ixz="0.0" iyy="0.0018795625" iyz="0.0" izz="0.0036638125"/>
    </inertial>
    <visual>
      <geometry>
        <mesh filename="package://thorvald_description/meshes/clamps/DUMMY-SUSP.stl"/>
        <box size="0.155 0.138 0.025"/>
      </geometry>
      <material name="alu"/>
    </visual>
    <collision>
      <geometry>
        <box size="0.155 0.138 0.025"/>
      </geometry>
    </collision>
  </link>


  <link name="corner1_4">
    <inertial>
      <mass value="0.915"/>
      <origin rpy="0 0 0" xyz="0 0 0"/>
      <inertia ixx="0.00149976125" ixy="0.0" ixz="0.0" iyy="0.0018795625" iyz="0.0" izz="0.0036638125"/>
    </inertial>
    <visual>
      <geometry>
        <mesh filename="package://thorvald_description/meshes/clamps/DUMMY-SUSP.stl"/>
        <box size="0.155 0.138 0.025"/>
      </geometry>
      <material name="alu"/>
    </visual>
    <collision>
      <geometry>
        <box size="0.155 0.138 0.025"/>
      </geometry>
    </collision>
  </link>
  <joint name="corner1_link_3" type="fixed">
    <parent link="corner1"/>
    <child link="corner1_3"/>
    <origin rpy="0 0.25 0" xyz="0.1 0 -0.075"/>
    <axis xyz="0 0 1"/>
  </joint>
  <joint name="corner1_link_4" type="fixed">
    <parent link="corner1"/>
    <child link="corner1_4"/>
    <origin rpy="0 0.25 0" xyz="0.1 0 0.075"/>
    <axis xyz="0 0 1"/>
  </joint>
  <joint name="corner1_link" type="fixed">
    <parent link="base_link"/>
    <child link="corner1"/>
    <origin rpy="0 0 0" xyz="0.368 -0.75 0.68221"/>
    <axis xyz="0 0 1"/>
  </joint>


  <link name="corner2_1">
    <inertial>
      <mass value="0.915"/>
      <origin rpy="0 0 0" xyz="0 0 0"/>
      <inertia ixx="0.001282525" ixy="0.0" ixz="0.0" iyy="0.001751005" iyz="0.0" izz="0.002989"/>
    </inertial>
    <visual>
      <geometry>
        <mesh filename="package://thorvald_description/meshes/clamps/DUMMY-T-BRACKET.stl"/>
        <box size="0.140 0.116 0.058"/>
      </geometry>
      <material name="alu"/>
    </visual>
    <collision>
      <geometry>
        <box size="0.140 0.116 0.058"/>
      </geometry>
    </collision>
  </link>


  <link name="corner2_2">
    <inertial>
      <mass value="0.915"/>
      <origin rpy="0 0 0" xyz="0 0 0"/>
      <inertia ixx="0.001282525" ixy="0.0" ixz="0.0" iyy="0.001751005" iyz="0.0" izz="0.002989"/>
    </inertial>
    <visual>
      <geometry>
        <mesh filename="package://thorvald_description/meshes/clamps/DUMMY-T-BRACKET.stl"/>
        <box size="0.140 0.116 0.058"/>
      </geometry>
      <material name="alu"/>
    </visual>
    <collision>
      <geometry>
        <box size="0.140 0.116 0.058"/>
      </geometry>
    </collision>
  </link>


  <link name="corner2">
    <inertial>
      <mass value="0.915"/>
      <origin rpy="0 0 0" xyz="0 0 0"/>
      <inertia ixx="0.001807125" ixy="0.0" ixz="0.0" iyy="0.001807125" iyz="0.0" izz="0.000183"/>
    </inertial>
    <visual>
      <geometry>
        <cylinder length="0.15" radius="0.02"/>
        <!-- <box size = "0.00001 0.00001 0.00001" /> -->
      </geometry>
      <material name="alu"/>
    </visual>
    <collision>
      <geometry>
        <cylinder length="0.15" radius="0.02"/>
      </geometry>
    </collision>
  </link>
  <joint name="corner2_link_1" type="fixed">
    <parent link="corner2"/>
    <child link="corner2_1"/>
    <origin rpy="0 0 0" xyz="0.057 0 -0.075"/>
    <axis xyz="0 0 1"/>
  </joint>
  <joint name="corner2_link_2" type="fixed">
    <parent link="corner2"/>
    <child link="corner2_2"/>
    <origin rpy="0 0 0" xyz="0.057 0 0.075"/>
    <axis xyz="0 0 1"/>
  </joint>


  <link name="corner2_3">
    <inertial>
      <mass value="0.915"/>
      <origin rpy="0 0 0" xyz="0 0 0"/>
      <inertia ixx="0.00149976125" ixy="0.0" ixz="0.0" iyy="0.0018795625" iyz="0.0" izz="0.0036638125"/>
    </inertial>
    <visual>
      <geometry>
        <mesh filename="package://thorvald_description/meshes/clamps/DUMMY-SUSP.stl"/>
        <box size="0.155 0.138 0.025"/>
      </geometry>
      <material name="alu"/>
    </visual>
    <collision>
      <geometry>
        <box size="0.155 0.138 0.025"/>
      </geometry>
    </collision>
  </link>


  <link name="corner2_4">
    <inertial>
      <mass value="0.915"/>
      <origin rpy="0 0 0" xyz="0 0 0"/>
      <inertia ixx="0.00149976125" ixy="0.0" ixz="0.0" iyy="0.0018795625" iyz="0.0" izz="0.0036638125"/>
    </inertial>
    <visual>
      <geometry>
        <mesh filename="package://thorvald_description/meshes/clamps/DUMMY-SUSP.stl"/>
        <box size="0.155 0.138 0.025"/>
      </geometry>
      <material name="alu"/>
    </visual>
    <collision>
      <geometry>
        <box size="0.155 0.138 0.025"/>
      </geometry>
    </collision>
  </link>
  <joint name="corner2_link_3" type="fixed">
    <parent link="corner2"/>
    <child link="corner2_3"/>
    <origin rpy="0 0.25 0" xyz="0.1 0 -0.075"/>
    <axis xyz="0 0 1"/>
  </joint>
  <joint name="corner2_link_4" type="fixed">
    <parent link="corner2"/>
    <child link="corner2_4"/>
    <origin rpy="0 0.25 0" xyz="0.1 0 0.075"/>
    <axis xyz="0 0 1"/>
  </joint>
  <joint name="corner2_link" type="fixed">
    <parent link="base_link"/>
    <child link="corner2"/>
    <origin rpy="0 0 0" xyz="0.368 0.75 0.68221"/>
    <axis xyz="0 0 1"/>
  </joint>


  <link name="corner3_1">
    <inertial>
      <mass value="0.915"/>
      <origin rpy="0 0 0" xyz="0 0 0"/>
      <inertia ixx="0.001282525" ixy="0.0" ixz="0.0" iyy="0.001751005" iyz="0.0" izz="0.002989"/>
    </inertial>
    <visual>
      <geometry>
        <mesh filename="package://thorvald_description/meshes/clamps/DUMMY-T-BRACKET.stl"/>
        <box size="0.140 0.116 0.058"/>
      </geometry>
      <material name="alu"/>
    </visual>
    <collision>
      <geometry>
        <box size="0.140 0.116 0.058"/>
      </geometry>
    </collision>
  </link>


  <link name="corner3_2">
    <inertial>
      <mass value="0.915"/>
      <origin rpy="0 0 0" xyz="0 0 0"/>
      <inertia ixx="0.001282525" ixy="0.0" ixz="0.0" iyy="0.001751005" iyz="0.0" izz="0.002989"/>
    </inertial>
    <visual>
      <geometry>
        <mesh filename="package://thorvald_description/meshes/clamps/DUMMY-T-BRACKET.stl"/>
        <box size="0.140 0.116 0.058"/>
      </geometry>
      <material name="alu"/>
    </visual>
    <collision>
      <geometry>
        <box size="0.140 0.116 0.058"/>
      </geometry>
    </collision>
  </link>


  <link name="corner3">
    <inertial>
      <mass value="0.915"/>
      <origin rpy="0 0 0" xyz="0 0 0"/>
      <inertia ixx="0.001807125" ixy="0.0" ixz="0.0" iyy="0.001807125" iyz="0.0" izz="0.000183"/>
    </inertial>
    <visual>
      <geometry>
        <cylinder length="0.15" radius="0.02"/>
        <!-- <box size = "0.00001 0.00001 0.00001" /> -->
      </geometry>
      <material name="alu"/>
    </visual>
    <collision>
      <geometry>
        <cylinder length="0.15" radius="0.02"/>
      </geometry>
    </collision>
  </link>
  <joint name="corner3_link_1" type="fixed">
    <parent link="corner3"/>
    <child link="corner3_1"/>
    <origin rpy="0 0 0" xyz="0.057 0 -0.075"/>
    <axis xyz="0 0 1"/>
  </joint>
  <joint name="corner3_link_2" type="fixed">
    <parent link="corner3"/>
    <child link="corner3_2"/>
    <origin rpy="0 0 0" xyz="0.057 0 0.075"/>
    <axis xyz="0 0 1"/>
  </joint>


  <link name="corner3_3">
    <inertial>
      <mass value="0.915"/>
      <origin rpy="0 0 0" xyz="0 0 0"/>
      <inertia ixx="0.00149976125" ixy="0.0" ixz="0.0" iyy="0.0018795625" iyz="0.0" izz="0.0036638125"/>
    </inertial>
    <visual>
      <geometry>
        <mesh filename="package://thorvald_description/meshes/clamps/DUMMY-SUSP.stl"/>
        <box size="0.155 0.138 0.025"/>
      </geometry>
      <material name="alu"/>
    </visual>
    <collision>
      <geometry>
        <box size="0.155 0.138 0.025"/>
      </geometry>
    </collision>
  </link>


  <link name="corner3_4">
    <inertial>
      <mass value="0.915"/>
      <origin rpy="0 0 0" xyz="0 0 0"/>
      <inertia ixx="0.00149976125" ixy="0.0" ixz="0.0" iyy="0.0018795625" iyz="0.0" izz="0.0036638125"/>
    </inertial>
    <visual>
      <geometry>
        <mesh filename="package://thorvald_description/meshes/clamps/DUMMY-SUSP.stl"/>
        <box size="0.155 0.138 0.025"/>
      </geometry>
      <material name="alu"/>
    </visual>
    <collision>
      <geometry>
        <box size="0.155 0.138 0.025"/>
      </geometry>
    </collision>
  </link>
  <joint name="corner3_link_3" type="fixed">
    <parent link="corner3"/>
    <child link="corner3_3"/>
    <origin rpy="0 0.25 0" xyz="0.1 0 -0.075"/>
    <axis xyz="0 0 1"/>
  </joint>
  <joint name="corner3_link_4" type="fixed">
    <parent link="corner3"/>
    <child link="corner3_4"/>
    <origin rpy="0 0.25 0" xyz="0.1 0 0.075"/>
    <axis xyz="0 0 1"/>
  </joint>
  <joint name="corner3_link" type="fixed">
    <parent link="base_link"/>
    <child link="corner3"/>
    <origin rpy="0 0 -3.14159265359" xyz="-0.368 0.75 0.68221"/>
    <axis xyz="0 0 1"/>
  </joint>


  <link name="pipe0_1">
    <inertial>
      <mass value="1"/>
      <origin rpy="0 0 0" xyz="0 0 0"/>
      <inertia ixx="0.0603083333333" ixy="0.0" ixz="0.0" iyy="0.0603083333333" iyz="0.0" izz="0.0002"/>
    </inertial>
    <visual>
      <geometry>
        <cylinder length="0.85" radius="0.02"/>
      </geometry>
      <material name="alu"/>
    </visual>
    <collision>
      <geometry>
        <cylinder length="0.85" radius="0.02"/>
      </geometry>
    </collision>
  </link>


  <link name="pipe0_2">
    <inertial>
      <mass value="1"/>
      <origin rpy="0 0 0" xyz="0 0 0"/>
      <inertia ixx="0.0603083333333" ixy="0.0" ixz="0.0" iyy="0.0603083333333" iyz="0.0" izz="0.0002"/>
    </inertial>
    <visual>
      <geometry>
        <cylinder length="0.85" radius="0.02"/>
      </geometry>
      <material name="alu"/>
    </visual>
    <collision>
      <geometry>
        <cylinder length="0.85" radius="0.02"/>
      </geometry>
    </collision>
  </link>
  <joint name="pipe0_link_1" type="fixed">
    <parent link="base_link"/>
    <child link="pipe0_1"/>
    <origin rpy="1.57079632679 0 -1.57079632679" xyz="0.0 -0.75 0.60721"/>
    <axis xyz="0 0 1"/>
  </joint>
  <joint name="pipe0_link_2" type="fixed">
    <parent link="base_link"/>
    <child link="pipe0_2"/>
    <origin rpy="1.57079632679 0 -1.57079632679" xyz="0.0 -0.75 0.75721"/>
    <axis xyz="0 0 1"/>
  </joint>


  <link name="pipe1_1">
    <inertial>
      <mass value="1"/>
      <origin rpy="0 0 0" xyz="0 0 0"/>
      <inertia ixx="0.1876" ixy="0.0" ixz="0.0" iyy="0.1876" iyz="0.0" izz="0.0002"/>
    </inertial>
    <visual>
      <geometry>
        <cylinder length="1.5" radius="0.02"/>
      </geometry>
      <material name="alu"/>
    </visual>
    <collision>
      <geometry>
        <cylinder length="1.5" radius="0.02"/>
      </geometry>
    </collision>
  </link>


  <link name="pipe1_2">
    <inertial>
      <mass value="1"/>
      <origin rpy="0 0 0" xyz="0 0 0"/>
      <inertia ixx="0.1876" ixy="0.0" ixz="0.0" iyy="0.1876" iyz="0.0" izz="0.0002"/>
    </inertial>
    <visual>
      <geometry>
        <cylinder length="1.5" radius="0.02"/>
      </geometry>
      <material name="alu"/>
    </visual>
    <collision>
      <geometry>
        <cylinder length="1.5" radius="0.02"/>
      </geometry>
    </collision>
  </link>
  <joint name="pipe1_link_1" type="fixed">
    <parent link="base_link"/>
    <child link="pipe1_1"/>
    <origin rpy="1.57079632679 0 0.0" xyz="0.425 0.0 0.60721"/>
    <axis xyz="0 0 1"/>
  </joint>
  <joint name="pipe1_link_2" type="fixed">
    <parent link="base_link"/>
    <child link="pipe1_2"/>
    <origin rpy="1.57079632679 0 0.0" xyz="0.425 0.0 0.75721"/>
    <axis xyz="0 0 1"/>
  </joint>


  <link name="pipe2_1">
    <inertial>
      <mass value="1"/>
      <origin rpy="0 0 0" xyz="0 0 0"/>
      <inertia ixx="0.0603083333333" ixy="0.0" ixz="0.0" iyy="0.0603083333333" iyz="0.0" izz="0.0002"/>
    </inertial>
    <visual>
      <geometry>
        <cylinder length="0.85" radius="0.02"/>
      </geometry>
      <material name="alu"/>
    </visual>
    <collision>
      <geometry>
        <cylinder length="0.85" radius="0.02"/>
      </geometry>
    </collision>
  </link>


  <link name="pipe2_2">
    <inertial>
      <mass value="1"/>
      <origin rpy="0 0 0" xyz="0 0 0"/>
      <inertia ixx="0.0603083333333" ixy="0.0" ixz="0.0" iyy="0.0603083333333" iyz="0.0" izz="0.0002"/>
    </inertial>
    <visual>
      <geometry>
        <cylinder length="0.85" radius="0.02"/>
      </geometry>
      <material name="alu"/>
    </visual>
    <collision>
      <geometry>
        <cylinder length="0.85" radius="0.02"/>
      </geometry>
    </collision>
  </link>
  <joint name="pipe2_link_1" type="fixed">
    <parent link="base_link"/>
    <child link="pipe2_1"/>
    <origin rpy="1.57079632679 0 1.57079632679" xyz="0.0 0.75 0.60721"/>
    <axis xyz="0 0 1"/>
  </joint>
  <joint name="pipe2_link_2" type="fixed">
    <parent link="base_link"/>
    <child link="pipe2_2"/>
    <origin rpy="1.57079632679 0 1.57079632679" xyz="0.0 0.75 0.75721"/>
    <axis xyz="0 0 1"/>
  </joint>


  <link name="pipe3_1">
    <inertial>
      <mass value="1"/>
      <origin rpy="0 0 0" xyz="0 0 0"/>
      <inertia ixx="0.1876" ixy="0.0" ixz="0.0" iyy="0.1876" iyz="0.0" izz="0.0002"/>
    </inertial>
    <visual>
      <geometry>
        <cylinder length="1.5" radius="0.02"/>
      </geometry>
      <material name="alu"/>
    </visual>
    <collision>
      <geometry>
        <cylinder length="1.5" radius="0.02"/>
      </geometry>
    </collision>
  </link>


  <link name="pipe3_2">
    <inertial>
      <mass value="1"/>
      <origin rpy="0 0 0" xyz="0 0 0"/>
      <inertia ixx="0.1876" ixy="0.0" ixz="0.0" iyy="0.1876" iyz="0.0" izz="0.0002"/>
    </inertial>
    <visual>
      <geometry>
        <cylinder length="1.5" radius="0.02"/>
      </geometry>
      <material name="alu"/>
    </visual>
    <collision>
      <geometry>
        <cylinder length="1.5" radius="0.02"/>
      </geometry>
    </collision>
  </link>
  <joint name="pipe3_link_1" type="fixed">
    <parent link="base_link"/>
    <child link="pipe3_1"/>
    <origin rpy="1.57079632679 0 -3.14159265359" xyz="-0.425 0.0 0.60721"/>
    <axis xyz="0 0 1"/>
  </joint>
  <joint name="pipe3_link_2" type="fixed">
    <parent link="base_link"/>
    <child link="pipe3_2"/>
    <origin rpy="1.57079632679 0 -3.14159265359" xyz="-0.425 0.0 0.75721"/>
    <axis xyz="0 0 1"/>
  </joint>


  <link name="pipe4_1">
    <inertial>
      <mass value="1"/>
      <origin rpy="0 0 0" xyz="0 0 0"/>
      <inertia ixx="0.247808333333" ixy="0.0" ixz="0.0" iyy="0.247808333333" iyz="0.0" izz="0.0002"/>
    </inertial>
    <visual>
      <geometry>
        <cylinder length="1.72409396496" radius="0.02"/>
      </geometry>
      <material name="alu"/>
    </visual>
    <collision>
      <geometry>
        <cylinder length="1.72409396496" radius="0.02"/>
      </geometry>
    </collision>
  </link>


  <link name="pipe4_2">
    <inertial>
      <mass value="1"/>
      <origin rpy="0 0 0" xyz="0 0 0"/>
      <inertia ixx="0.247808333333" ixy="0.0" ixz="0.0" iyy="0.247808333333" iyz="0.0" izz="0.0002"/>
    </inertial>
    <visual>
      <geometry>
        <cylinder length="1.72409396496" radius="0.02"/>
      </geometry>
      <material name="alu"/>
    </visual>
    <collision>
      <geometry>
        <cylinder length="1.72409396496" radius="0.02"/>
      </geometry>
    </collision>
  </link>
  <joint name="pipe4_link_1" type="fixed">
    <parent link="base_link"/>
    <child link="pipe4_1"/>
    <origin rpy="1.57079632679 0 -0.515549007459" xyz="0.0 0.0 0.60721"/>
    <axis xyz="0 0 1"/>
  </joint>
  <joint name="pipe4_link_2" type="fixed">
    <parent link="base_link"/>
    <child link="pipe4_2"/>
    <origin rpy="1.57079632679 0 -0.515549007459" xyz="0.0 0.0 0.75721"/>
    <axis xyz="0 0 1"/>
  </joint>


  <link name="bat0">
    <inertial>
      <mass value="12.88"/>
      <origin rpy="0 0 0" xyz="0 0 -0.25"/>
      <inertia ixx="0.342507106667" ixy="0.0" ixz="0.0" iyy="0.579579606667" iyz="0.0" izz="0.602998666667"/>
    </inertial>
    <visual>
      <origin rpy="0 0 0" xyz="0 0 0"/>
      <geometry>
        <mesh filename="package://thorvald_description/meshes/bat_enc_modules/836586-1-DUMMY-RevA.stl"/>
        <box size="0.530 0.245 0.509"/>
      </geometry>
      <material name="white"/>
    </visual>
    <collision>
      <geometry>
        <mesh filename="package://thorvald_description/meshes/bat_enc_modules/836586-1-DUMMY-RevA.stl"/>
        <box size="0.530 0.245 0.509"/>
      </geometry>
    </collision>
  </link>
  <joint name="bat0_joint" type="fixed">
    <parent link="base_link"/>
    <child link="bat0"/>
    <origin rpy="0 0 3.14159265359" xyz="0.0 0.75 0.75721"/>
    <axis xyz="0 0 1"/>
  </joint>


  <link name="bat1">
    <inertial>
      <mass value="12.88"/>
      <origin rpy="0 0 0" xyz="0 0 -0.25"/>
      <inertia ixx="0.342507106667" ixy="0.0" ixz="0.0" iyy="0.579579606667" iyz="0.0" izz="0.602998666667"/>
    </inertial>
    <visual>
      <origin rpy="0 0 0" xyz="0 0 0"/>
      <geometry>
        <mesh filename="package://thorvald_description/meshes/bat_enc_modules/836586-1-DUMMY-RevA.stl"/>
        <box size="0.530 0.245 0.509"/>
      </geometry>
      <material name="white"/>
    </visual>
    <collision>
      <geometry>
        <mesh filename="package://thorvald_description/meshes/bat_enc_modules/836586-1-DUMMY-RevA.stl"/>
        <box size="0.530 0.245 0.509"/>
      </geometry>
    </collision>
  </link>
  <joint name="bat1_joint" type="fixed">
    <parent link="base_link"/>
    <child link="bat1"/>
    <origin rpy="0 0 0" xyz="0.0 -0.75 0.75721"/>
    <axis xyz="0 0 1"/>
  </joint>


  <link name="base_sensors"/>
  <link name="gps_frame"/>
  <link name="imu_frame"/>
  <link name="laser_frame"/>
  <joint name="base_base_sens" type="fixed">
    <parent link="base_link"/>
    <child link="base_sensors"/>
    <origin rpy="0 0 0" xyz="0.67 0 0.6"/>
  </joint>
  <joint name="base_sens_gps_frame" type="fixed">
    <parent link="base_sensors"/>
    <child link="gps_frame"/>
    <origin rpy="0 0 0" xyz="-0.01 0 0.3"/>
  </joint>
  <joint name="base_sens_imu_frame" type="fixed">
    <parent link="base_sensors"/>
    <child link="imu_frame"/>
    <origin rpy="0 0 0" xyz="0.05 0 0"/>
  </joint>
  <joint name="base_sens_laser_frame" type="fixed">
    <parent link="base_sensors"/>
    <child link="laser_frame"/>
    <origin rpy="0 0 0" xyz="0.10 0. 0"/>
  </joint>

  <gazebo>
    <plugin name="gazebo_ros_control" filename="libgazebo_ros_control.so">
      <robotNamespace>/thorvald</robotNamespace>
    </plugin>
  </gazebo>

  <!-- Sensors. -->
  <xacro:realsense_t265 robot_ns="thorvald/" sensor_name="t265_camera" parent_link="imu_frame" rate="30.0">
    <origin rpy="0 0 0" xyz="0 0 0"/>
  </xacro:realsense_t265>

</robot>


