<sdf version='1.6'>
  <world name='default'>
    <light name='sun' type='directional'>
      <cast_shadows>1</cast_shadows>
      <pose frame=''>0 0 10 0 -0 0</pose>
      <diffuse>0.8 0.8 0.8 1</diffuse>
      <specular>0.2 0.2 0.2 1</specular>
      <attenuation>
        <range>1000</range>
        <constant>0.9</constant>
        <linear>0.01</linear>
        <quadratic>0.001</quadratic>
      </attenuation>
      <direction>-0.5 0.1 -0.9</direction>
    </light>
    <model name='ground_plane'>
      <static>1</static>
      <link name='link'>
        <collision name='collision'>
          <geometry>
            <plane>
              <normal>0 0 1</normal>
              <size>100 100</size>
            </plane>
          </geometry>
          <surface>
            <contact>
              <collide_bitmask>65535</collide_bitmask>
              <ode/>
            </contact>
            <friction>
              <ode>
                <mu>100</mu>
                <mu2>50</mu2>
              </ode>
              <torsional>
                <ode/>
              </torsional>
            </friction>
            <bounce/>
          </surface>
          <max_contacts>10</max_contacts>
        </collision>
        <visual name='visual'>
          <cast_shadows>0</cast_shadows>
          <geometry>
            <plane>
              <normal>0 0 1</normal>
              <size>100 100</size>
            </plane>
          </geometry>
          <material>
            <script>
              <uri>file://media/materials/scripts/gazebo.material</uri>
              <name>Gazebo/Grey</name>
            </script>
          </material>
        </visual>
        <self_collide>0</self_collide>
        <enable_wind>0</enable_wind>
        <kinematic>0</kinematic>
      </link>
    </model>
    <gravity>0 0 -9.8</gravity>
    <magnetic_field>6e-06 2.3e-05 -4.2e-05</magnetic_field>
    <atmosphere type='adiabatic'/>
    <physics name='default_physics' default='0' type='ode'>
      <max_step_size>0.001</max_step_size>
      <real_time_factor>1</real_time_factor>
      <real_time_update_rate>1000</real_time_update_rate>
    </physics>
    <scene>
      <ambient>0.4 0.4 0.4 1</ambient>
      <background>0.7 0.7 0.7 1</background>
      <shadows>1</shadows>
    </scene>
    <audio>
      <device>default</device>
    </audio>
    <wind/>
    <spherical_coordinates>
      <surface_model>EARTH_WGS84</surface_model>
      <latitude_deg>0</latitude_deg>
      <longitude_deg>0</longitude_deg>
      <elevation>0</elevation>
      <heading_deg>0</heading_deg>
    </spherical_coordinates>
    <model name='robot'>
      <link name='base_link'>
        <pose frame=''>0 0 0 0 -0 0</pose>
        <inertial>
          <pose frame=''>-0 0 0.620846 0 -0 0</pose>
          <mass>94.9</mass>
          <inertia>
            <ixx>53.2098</ixx>
            <ixy>-0.212414</ixy>
            <ixz>1.19496e-12</ixz>
            <iyy>25.9227</iyy>
            <iyz>2.10298e-12</iyz>
            <izz>76.143</izz>
          </inertia>
        </inertial>
        <collision name='base_link_fixed_joint_lump__top0_collision'>
          <pose frame=''>-0.67792 -0.75 0.65 0 -0 -3.14159</pose>
          <geometry>
            <mesh>
              <scale>1 1 1</scale>
              <uri>/opt/ros/melodic/share/thorvald_description/meshes/tower_modules/DUMMY-TOWER-M.stl</uri>
            </mesh>
          </geometry>
          <max_contacts>10</max_contacts>
          <surface>
            <contact>
              <ode/>
            </contact>
            <bounce/>
            <friction>
              <torsional>
                <ode/>
              </torsional>
              <ode/>
            </friction>
          </surface>
        </collision>
        <collision name='base_link_fixed_joint_lump__top1_collision_1'>
          <pose frame=''>0.67792 -0.75 0.65 0 -0 0</pose>
          <geometry>
            <mesh>
              <scale>1 1 1</scale>
              <uri>/opt/ros/melodic/share/thorvald_description/meshes/tower_modules/DUMMY-TOWER-MIRROR-M.stl</uri>
            </mesh>
          </geometry>
          <max_contacts>10</max_contacts>
          <surface>
            <contact>
              <ode/>
            </contact>
            <bounce/>
            <friction>
              <torsional>
                <ode/>
              </torsional>
              <ode/>
            </friction>
          </surface>
        </collision>
        <collision name='base_link_fixed_joint_lump__top2_collision_2'>
          <pose frame=''>0.67792 0.75 0.65 0 -0 0</pose>
          <geometry>
            <mesh>
              <scale>1 1 1</scale>
              <uri>/opt/ros/melodic/share/thorvald_description/meshes/tower_modules/DUMMY-TOWER-M.stl</uri>
            </mesh>
          </geometry>
          <max_contacts>10</max_contacts>
          <surface>
            <contact>
              <ode/>
            </contact>
            <bounce/>
            <friction>
              <torsional>
                <ode/>
              </torsional>
              <ode/>
            </friction>
          </surface>
        </collision>
        <collision name='base_link_fixed_joint_lump__top3_collision_3'>
          <pose frame=''>-0.67792 0.75 0.65 0 -0 -3.14159</pose>
          <geometry>
            <mesh>
              <scale>1 1 1</scale>
              <uri>/opt/ros/melodic/share/thorvald_description/meshes/tower_modules/DUMMY-TOWER-MIRROR-M.stl</uri>
            </mesh>
          </geometry>
          <max_contacts>10</max_contacts>
          <surface>
            <contact>
              <ode/>
            </contact>
            <bounce/>
            <friction>
              <torsional>
                <ode/>
              </torsional>
              <ode/>
            </friction>
          </surface>
        </collision>
        <collision name='base_link_fixed_joint_lump__bat0_collision_4'>
          <pose frame=''>0 0.75 0.75721 0 -0 -3.14159</pose>
          <geometry>
            <mesh>
              <scale>1 1 1</scale>
              <uri>/opt/ros/melodic/share/thorvald_description/meshes/bat_enc_modules/836586-1-DUMMY-RevA.stl</uri>
            </mesh>
          </geometry>
          <max_contacts>10</max_contacts>
          <surface>
            <contact>
              <ode/>
            </contact>
            <bounce/>
            <friction>
              <torsional>
                <ode/>
              </torsional>
              <ode/>
            </friction>
          </surface>
        </collision>
        <collision name='base_link_fixed_joint_lump__bat1_collision_5'>
          <pose frame=''>0 -0.75 0.75721 0 -0 0</pose>
          <geometry>
            <mesh>
              <scale>1 1 1</scale>
              <uri>/opt/ros/melodic/share/thorvald_description/meshes/bat_enc_modules/836586-1-DUMMY-RevA.stl</uri>
            </mesh>
          </geometry>
          <max_contacts>10</max_contacts>
          <surface>
            <contact>
              <ode/>
            </contact>
            <bounce/>
            <friction>
              <torsional>
                <ode/>
              </torsional>
              <ode/>
            </friction>
          </surface>
        </collision>
        <collision name='base_link_fixed_joint_lump__corner0_collision_6'>
          <pose frame=''>-0.368 -0.75 0.68221 0 -0 3.14159</pose>
          <geometry>
            <cylinder>
              <length>0.15</length>
              <radius>0.02</radius>
            </cylinder>
          </geometry>
          <max_contacts>10</max_contacts>
          <surface>
            <contact>
              <ode/>
            </contact>
            <bounce/>
            <friction>
              <torsional>
                <ode/>
              </torsional>
              <ode/>
            </friction>
          </surface>
        </collision>
        <collision name='base_link_fixed_joint_lump__corner0_1_collision_7'>
          <pose frame=''>-0.425 -0.75 0.60721 0 -0 3.14159</pose>
          <geometry>
            <box>
              <size>0.14 0.116 0.058</size>
            </box>
          </geometry>
          <max_contacts>10</max_contacts>
          <surface>
            <contact>
              <ode/>
            </contact>
            <bounce/>
            <friction>
              <torsional>
                <ode/>
              </torsional>
              <ode/>
            </friction>
          </surface>
        </collision>
        <collision name='base_link_fixed_joint_lump__corner0_2_collision_8'>
          <pose frame=''>-0.425 -0.75 0.75721 0 -0 3.14159</pose>
          <geometry>
            <box>
              <size>0.14 0.116 0.058</size>
            </box>
          </geometry>
          <max_contacts>10</max_contacts>
          <surface>
            <contact>
              <ode/>
            </contact>
            <bounce/>
            <friction>
              <torsional>
                <ode/>
              </torsional>
              <ode/>
            </friction>
          </surface>
        </collision>
        <collision name='base_link_fixed_joint_lump__corner0_3_collision_9'>
          <pose frame=''>-0.468 -0.75 0.60721 0 0.25 3.14159</pose>
          <geometry>
            <box>
              <size>0.155 0.138 0.025</size>
            </box>
          </geometry>
          <max_contacts>10</max_contacts>
          <surface>
            <contact>
              <ode/>
            </contact>
            <bounce/>
            <friction>
              <torsional>
                <ode/>
              </torsional>
              <ode/>
            </friction>
          </surface>
        </collision>
        <collision name='base_link_fixed_joint_lump__corner0_4_collision_10'>
          <pose frame=''>-0.468 -0.75 0.75721 0 0.25 3.14159</pose>
          <geometry>
            <box>
              <size>0.155 0.138 0.025</size>
            </box>
          </geometry>
          <max_contacts>10</max_contacts>
          <surface>
            <contact>
              <ode/>
            </contact>
            <bounce/>
            <friction>
              <torsional>
                <ode/>
              </torsional>
              <ode/>
            </friction>
          </surface>
        </collision>
        <collision name='base_link_fixed_joint_lump__corner1_collision_11'>
          <pose frame=''>0.368 -0.75 0.68221 0 -0 0</pose>
          <geometry>
            <cylinder>
              <length>0.15</length>
              <radius>0.02</radius>
            </cylinder>
          </geometry>
          <max_contacts>10</max_contacts>
          <surface>
            <contact>
              <ode/>
            </contact>
            <bounce/>
            <friction>
              <torsional>
                <ode/>
              </torsional>
              <ode/>
            </friction>
          </surface>
        </collision>
        <collision name='base_link_fixed_joint_lump__corner1_1_collision_12'>
          <pose frame=''>0.425 -0.75 0.60721 0 -0 0</pose>
          <geometry>
            <box>
              <size>0.14 0.116 0.058</size>
            </box>
          </geometry>
          <max_contacts>10</max_contacts>
          <surface>
            <contact>
              <ode/>
            </contact>
            <bounce/>
            <friction>
              <torsional>
                <ode/>
              </torsional>
              <ode/>
            </friction>
          </surface>
        </collision>
        <collision name='base_link_fixed_joint_lump__corner1_2_collision_13'>
          <pose frame=''>0.425 -0.75 0.75721 0 -0 0</pose>
          <geometry>
            <box>
              <size>0.14 0.116 0.058</size>
            </box>
          </geometry>
          <max_contacts>10</max_contacts>
          <surface>
            <contact>
              <ode/>
            </contact>
            <bounce/>
            <friction>
              <torsional>
                <ode/>
              </torsional>
              <ode/>
            </friction>
          </surface>
        </collision>
        <collision name='base_link_fixed_joint_lump__corner1_3_collision_14'>
          <pose frame=''>0.468 -0.75 0.60721 0 0.25 0</pose>
          <geometry>
            <box>
              <size>0.155 0.138 0.025</size>
            </box>
          </geometry>
          <max_contacts>10</max_contacts>
          <surface>
            <contact>
              <ode/>
            </contact>
            <bounce/>
            <friction>
              <torsional>
                <ode/>
              </torsional>
              <ode/>
            </friction>
          </surface>
        </collision>
        <collision name='base_link_fixed_joint_lump__corner1_4_collision_15'>
          <pose frame=''>0.468 -0.75 0.75721 0 0.25 0</pose>
          <geometry>
            <box>
              <size>0.155 0.138 0.025</size>
            </box>
          </geometry>
          <max_contacts>10</max_contacts>
          <surface>
            <contact>
              <ode/>
            </contact>
            <bounce/>
            <friction>
              <torsional>
                <ode/>
              </torsional>
              <ode/>
            </friction>
          </surface>
        </collision>
        <collision name='base_link_fixed_joint_lump__corner2_collision_16'>
          <pose frame=''>0.368 0.75 0.68221 0 -0 0</pose>
          <geometry>
            <cylinder>
              <length>0.15</length>
              <radius>0.02</radius>
            </cylinder>
          </geometry>
          <max_contacts>10</max_contacts>
          <surface>
            <contact>
              <ode/>
            </contact>
            <bounce/>
            <friction>
              <torsional>
                <ode/>
              </torsional>
              <ode/>
            </friction>
          </surface>
        </collision>
        <collision name='base_link_fixed_joint_lump__corner2_1_collision_17'>
          <pose frame=''>0.425 0.75 0.60721 0 -0 0</pose>
          <geometry>
            <box>
              <size>0.14 0.116 0.058</size>
            </box>
          </geometry>
          <max_contacts>10</max_contacts>
          <surface>
            <contact>
              <ode/>
            </contact>
            <bounce/>
            <friction>
              <torsional>
                <ode/>
              </torsional>
              <ode/>
            </friction>
          </surface>
        </collision>
        <collision name='base_link_fixed_joint_lump__corner2_2_collision_18'>
          <pose frame=''>0.425 0.75 0.75721 0 -0 0</pose>
          <geometry>
            <box>
              <size>0.14 0.116 0.058</size>
            </box>
          </geometry>
          <max_contacts>10</max_contacts>
          <surface>
            <contact>
              <ode/>
            </contact>
            <bounce/>
            <friction>
              <torsional>
                <ode/>
              </torsional>
              <ode/>
            </friction>
          </surface>
        </collision>
        <collision name='base_link_fixed_joint_lump__corner2_3_collision_19'>
          <pose frame=''>0.468 0.75 0.60721 0 0.25 0</pose>
          <geometry>
            <box>
              <size>0.155 0.138 0.025</size>
            </box>
          </geometry>
          <max_contacts>10</max_contacts>
          <surface>
            <contact>
              <ode/>
            </contact>
            <bounce/>
            <friction>
              <torsional>
                <ode/>
              </torsional>
              <ode/>
            </friction>
          </surface>
        </collision>
        <collision name='base_link_fixed_joint_lump__corner2_4_collision_20'>
          <pose frame=''>0.468 0.75 0.75721 0 0.25 0</pose>
          <geometry>
            <box>
              <size>0.155 0.138 0.025</size>
            </box>
          </geometry>
          <max_contacts>10</max_contacts>
          <surface>
            <contact>
              <ode/>
            </contact>
            <bounce/>
            <friction>
              <torsional>
                <ode/>
              </torsional>
              <ode/>
            </friction>
          </surface>
        </collision>
        <collision name='base_link_fixed_joint_lump__corner3_collision_21'>
          <pose frame=''>-0.368 0.75 0.68221 0 -0 3.14159</pose>
          <geometry>
            <cylinder>
              <length>0.15</length>
              <radius>0.02</radius>
            </cylinder>
          </geometry>
          <max_contacts>10</max_contacts>
          <surface>
            <contact>
              <ode/>
            </contact>
            <bounce/>
            <friction>
              <torsional>
                <ode/>
              </torsional>
              <ode/>
            </friction>
          </surface>
        </collision>
        <collision name='base_link_fixed_joint_lump__corner3_1_collision_22'>
          <pose frame=''>-0.425 0.75 0.60721 0 -0 3.14159</pose>
          <geometry>
            <box>
              <size>0.14 0.116 0.058</size>
            </box>
          </geometry>
          <max_contacts>10</max_contacts>
          <surface>
            <contact>
              <ode/>
            </contact>
            <bounce/>
            <friction>
              <torsional>
                <ode/>
              </torsional>
              <ode/>
            </friction>
          </surface>
        </collision>
        <collision name='base_link_fixed_joint_lump__corner3_2_collision_23'>
          <pose frame=''>-0.425 0.75 0.75721 0 -0 3.14159</pose>
          <geometry>
            <box>
              <size>0.14 0.116 0.058</size>
            </box>
          </geometry>
          <max_contacts>10</max_contacts>
          <surface>
            <contact>
              <ode/>
            </contact>
            <bounce/>
            <friction>
              <torsional>
                <ode/>
              </torsional>
              <ode/>
            </friction>
          </surface>
        </collision>
        <collision name='base_link_fixed_joint_lump__corner3_3_collision_24'>
          <pose frame=''>-0.468 0.75 0.60721 0 0.25 3.14159</pose>
          <geometry>
            <box>
              <size>0.155 0.138 0.025</size>
            </box>
          </geometry>
          <max_contacts>10</max_contacts>
          <surface>
            <contact>
              <ode/>
            </contact>
            <bounce/>
            <friction>
              <torsional>
                <ode/>
              </torsional>
              <ode/>
            </friction>
          </surface>
        </collision>
        <collision name='base_link_fixed_joint_lump__corner3_4_collision_25'>
          <pose frame=''>-0.468 0.75 0.75721 0 0.25 3.14159</pose>
          <geometry>
            <box>
              <size>0.155 0.138 0.025</size>
            </box>
          </geometry>
          <max_contacts>10</max_contacts>
          <surface>
            <contact>
              <ode/>
            </contact>
            <bounce/>
            <friction>
              <torsional>
                <ode/>
              </torsional>
              <ode/>
            </friction>
          </surface>
        </collision>
        <collision name='base_link_fixed_joint_lump__pipe0_1_collision_26'>
          <pose frame=''>0 -0.75 0.60721 1.5708 0 -1.5708</pose>
          <geometry>
            <cylinder>
              <length>0.85</length>
              <radius>0.02</radius>
            </cylinder>
          </geometry>
          <max_contacts>10</max_contacts>
          <surface>
            <contact>
              <ode/>
            </contact>
            <bounce/>
            <friction>
              <torsional>
                <ode/>
              </torsional>
              <ode/>
            </friction>
          </surface>
        </collision>
        <collision name='base_link_fixed_joint_lump__pipe0_2_collision_27'>
          <pose frame=''>0 -0.75 0.75721 1.5708 0 -1.5708</pose>
          <geometry>
            <cylinder>
              <length>0.85</length>
              <radius>0.02</radius>
            </cylinder>
          </geometry>
          <max_contacts>10</max_contacts>
          <surface>
            <contact>
              <ode/>
            </contact>
            <bounce/>
            <friction>
              <torsional>
                <ode/>
              </torsional>
              <ode/>
            </friction>
          </surface>
        </collision>
        <collision name='base_link_fixed_joint_lump__pipe1_1_collision_28'>
          <pose frame=''>0.425 0 0.60721 1.5708 -0 0</pose>
          <geometry>
            <cylinder>
              <length>1.5</length>
              <radius>0.02</radius>
            </cylinder>
          </geometry>
          <max_contacts>10</max_contacts>
          <surface>
            <contact>
              <ode/>
            </contact>
            <bounce/>
            <friction>
              <torsional>
                <ode/>
              </torsional>
              <ode/>
            </friction>
          </surface>
        </collision>
        <collision name='base_link_fixed_joint_lump__pipe1_2_collision_29'>
          <pose frame=''>0.425 0 0.75721 1.5708 -0 0</pose>
          <geometry>
            <cylinder>
              <length>1.5</length>
              <radius>0.02</radius>
            </cylinder>
          </geometry>
          <max_contacts>10</max_contacts>
          <surface>
            <contact>
              <ode/>
            </contact>
            <bounce/>
            <friction>
              <torsional>
                <ode/>
              </torsional>
              <ode/>
            </friction>
          </surface>
        </collision>
        <collision name='base_link_fixed_joint_lump__pipe2_1_collision_30'>
          <pose frame=''>0 0.75 0.60721 1.5708 -0 1.5708</pose>
          <geometry>
            <cylinder>
              <length>0.85</length>
              <radius>0.02</radius>
            </cylinder>
          </geometry>
          <max_contacts>10</max_contacts>
          <surface>
            <contact>
              <ode/>
            </contact>
            <bounce/>
            <friction>
              <torsional>
                <ode/>
              </torsional>
              <ode/>
            </friction>
          </surface>
        </collision>
        <collision name='base_link_fixed_joint_lump__pipe2_2_collision_31'>
          <pose frame=''>0 0.75 0.75721 1.5708 -0 1.5708</pose>
          <geometry>
            <cylinder>
              <length>0.85</length>
              <radius>0.02</radius>
            </cylinder>
          </geometry>
          <max_contacts>10</max_contacts>
          <surface>
            <contact>
              <ode/>
            </contact>
            <bounce/>
            <friction>
              <torsional>
                <ode/>
              </torsional>
              <ode/>
            </friction>
          </surface>
        </collision>
        <collision name='base_link_fixed_joint_lump__pipe3_1_collision_32'>
          <pose frame=''>-0.425 0 0.60721 1.5708 -0 3.14159</pose>
          <geometry>
            <cylinder>
              <length>1.5</length>
              <radius>0.02</radius>
            </cylinder>
          </geometry>
          <max_contacts>10</max_contacts>
          <surface>
            <contact>
              <ode/>
            </contact>
            <bounce/>
            <friction>
              <torsional>
                <ode/>
              </torsional>
              <ode/>
            </friction>
          </surface>
        </collision>
        <collision name='base_link_fixed_joint_lump__pipe3_2_collision_33'>
          <pose frame=''>-0.425 0 0.75721 1.5708 -0 3.14159</pose>
          <geometry>
            <cylinder>
              <length>1.5</length>
              <radius>0.02</radius>
            </cylinder>
          </geometry>
          <max_contacts>10</max_contacts>
          <surface>
            <contact>
              <ode/>
            </contact>
            <bounce/>
            <friction>
              <torsional>
                <ode/>
              </torsional>
              <ode/>
            </friction>
          </surface>
        </collision>
        <collision name='base_link_fixed_joint_lump__pipe4_1_collision_34'>
          <pose frame=''>0 0 0.60721 1.5708 -0 -0.515549</pose>
          <geometry>
            <cylinder>
              <length>1.72409</length>
              <radius>0.02</radius>
            </cylinder>
          </geometry>
          <max_contacts>10</max_contacts>
          <surface>
            <contact>
              <ode/>
            </contact>
            <bounce/>
            <friction>
              <torsional>
                <ode/>
              </torsional>
              <ode/>
            </friction>
          </surface>
        </collision>
        <collision name='base_link_fixed_joint_lump__pipe4_2_collision_35'>
          <pose frame=''>0 0 0.75721 1.5708 -0 -0.515549</pose>
          <geometry>
            <cylinder>
              <length>1.72409</length>
              <radius>0.02</radius>
            </cylinder>
          </geometry>
          <max_contacts>10</max_contacts>
          <surface>
            <contact>
              <ode/>
            </contact>
            <bounce/>
            <friction>
              <torsional>
                <ode/>
              </torsional>
              <ode/>
            </friction>
          </surface>
        </collision>
        <visual name='base_link_fixed_joint_lump__top0_visual'>
          <pose frame=''>-0.67792 -0.75 0.65 0 -0 -3.14159</pose>
          <geometry>
            <mesh>
              <scale>1 1 1</scale>
              <uri>/opt/ros/melodic/share/thorvald_description/meshes/tower_modules/DUMMY-TOWER-M.stl</uri>
            </mesh>
          </geometry>
        </visual>
        <visual name='base_link_fixed_joint_lump__top1_visual_1'>
          <pose frame=''>0.67792 -0.75 0.65 0 -0 0</pose>
          <geometry>
            <mesh>
              <scale>1 1 1</scale>
              <uri>/opt/ros/melodic/share/thorvald_description/meshes/tower_modules/DUMMY-TOWER-MIRROR-M.stl</uri>
            </mesh>
          </geometry>
        </visual>
        <visual name='base_link_fixed_joint_lump__top2_visual_2'>
          <pose frame=''>0.67792 0.75 0.65 0 -0 0</pose>
          <geometry>
            <mesh>
              <scale>1 1 1</scale>
              <uri>/opt/ros/melodic/share/thorvald_description/meshes/tower_modules/DUMMY-TOWER-M.stl</uri>
            </mesh>
          </geometry>
        </visual>
        <visual name='base_link_fixed_joint_lump__top3_visual_3'>
          <pose frame=''>-0.67792 0.75 0.65 0 -0 -3.14159</pose>
          <geometry>
            <mesh>
              <scale>1 1 1</scale>
              <uri>/opt/ros/melodic/share/thorvald_description/meshes/tower_modules/DUMMY-TOWER-MIRROR-M.stl</uri>
            </mesh>
          </geometry>
        </visual>
        <visual name='base_link_fixed_joint_lump__bat0_visual_4'>
          <pose frame=''>0 0.75 0.75721 0 -0 -3.14159</pose>
          <geometry>
            <mesh>
              <scale>1 1 1</scale>
              <uri>/opt/ros/melodic/share/thorvald_description/meshes/bat_enc_modules/836586-1-DUMMY-RevA.stl</uri>
            </mesh>
          </geometry>
        </visual>
        <visual name='base_link_fixed_joint_lump__bat1_visual_5'>
          <pose frame=''>0 -0.75 0.75721 0 -0 0</pose>
          <geometry>
            <mesh>
              <scale>1 1 1</scale>
              <uri>/opt/ros/melodic/share/thorvald_description/meshes/bat_enc_modules/836586-1-DUMMY-RevA.stl</uri>
            </mesh>
          </geometry>
        </visual>
        <visual name='base_link_fixed_joint_lump__corner0_visual_6'>
          <pose frame=''>-0.368 -0.75 0.68221 0 -0 3.14159</pose>
          <geometry>
            <cylinder>
              <length>0.15</length>
              <radius>0.02</radius>
            </cylinder>
          </geometry>
        </visual>
        <visual name='base_link_fixed_joint_lump__corner0_1_visual_7'>
          <pose frame=''>-0.425 -0.75 0.60721 0 -0 3.14159</pose>
          <geometry>
            <mesh>
              <scale>1 1 1</scale>
              <uri>/opt/ros/melodic/share/thorvald_description/meshes/clamps/DUMMY-T-BRACKET.stl</uri>
            </mesh>
          </geometry>
        </visual>
        <visual name='base_link_fixed_joint_lump__corner0_2_visual_8'>
          <pose frame=''>-0.425 -0.75 0.75721 0 -0 3.14159</pose>
          <geometry>
            <mesh>
              <scale>1 1 1</scale>
              <uri>/opt/ros/melodic/share/thorvald_description/meshes/clamps/DUMMY-T-BRACKET.stl</uri>
            </mesh>
          </geometry>
        </visual>
        <visual name='base_link_fixed_joint_lump__corner0_3_visual_9'>
          <pose frame=''>-0.468 -0.75 0.60721 0 0.25 3.14159</pose>
          <geometry>
            <mesh>
              <scale>1 1 1</scale>
              <uri>/opt/ros/melodic/share/thorvald_description/meshes/clamps/DUMMY-SUSP.stl</uri>
            </mesh>
          </geometry>
        </visual>
        <visual name='base_link_fixed_joint_lump__corner0_4_visual_10'>
          <pose frame=''>-0.468 -0.75 0.75721 0 0.25 3.14159</pose>
          <geometry>
            <mesh>
              <scale>1 1 1</scale>
              <uri>/opt/ros/melodic/share/thorvald_description/meshes/clamps/DUMMY-SUSP.stl</uri>
            </mesh>
          </geometry>
        </visual>
        <visual name='base_link_fixed_joint_lump__corner1_visual_11'>
          <pose frame=''>0.368 -0.75 0.68221 0 -0 0</pose>
          <geometry>
            <cylinder>
              <length>0.15</length>
              <radius>0.02</radius>
            </cylinder>
          </geometry>
        </visual>
        <visual name='base_link_fixed_joint_lump__corner1_1_visual_12'>
          <pose frame=''>0.425 -0.75 0.60721 0 -0 0</pose>
          <geometry>
            <mesh>
              <scale>1 1 1</scale>
              <uri>/opt/ros/melodic/share/thorvald_description/meshes/clamps/DUMMY-T-BRACKET.stl</uri>
            </mesh>
          </geometry>
        </visual>
        <visual name='base_link_fixed_joint_lump__corner1_2_visual_13'>
          <pose frame=''>0.425 -0.75 0.75721 0 -0 0</pose>
          <geometry>
            <mesh>
              <scale>1 1 1</scale>
              <uri>/opt/ros/melodic/share/thorvald_description/meshes/clamps/DUMMY-T-BRACKET.stl</uri>
            </mesh>
          </geometry>
        </visual>
        <visual name='base_link_fixed_joint_lump__corner1_3_visual_14'>
          <pose frame=''>0.468 -0.75 0.60721 0 0.25 0</pose>
          <geometry>
            <mesh>
              <scale>1 1 1</scale>
              <uri>/opt/ros/melodic/share/thorvald_description/meshes/clamps/DUMMY-SUSP.stl</uri>
            </mesh>
          </geometry>
        </visual>
        <visual name='base_link_fixed_joint_lump__corner1_4_visual_15'>
          <pose frame=''>0.468 -0.75 0.75721 0 0.25 0</pose>
          <geometry>
            <mesh>
              <scale>1 1 1</scale>
              <uri>/opt/ros/melodic/share/thorvald_description/meshes/clamps/DUMMY-SUSP.stl</uri>
            </mesh>
          </geometry>
        </visual>
        <visual name='base_link_fixed_joint_lump__corner2_visual_16'>
          <pose frame=''>0.368 0.75 0.68221 0 -0 0</pose>
          <geometry>
            <cylinder>
              <length>0.15</length>
              <radius>0.02</radius>
            </cylinder>
          </geometry>
        </visual>
        <visual name='base_link_fixed_joint_lump__corner2_1_visual_17'>
          <pose frame=''>0.425 0.75 0.60721 0 -0 0</pose>
          <geometry>
            <mesh>
              <scale>1 1 1</scale>
              <uri>/opt/ros/melodic/share/thorvald_description/meshes/clamps/DUMMY-T-BRACKET.stl</uri>
            </mesh>
          </geometry>
        </visual>
        <visual name='base_link_fixed_joint_lump__corner2_2_visual_18'>
          <pose frame=''>0.425 0.75 0.75721 0 -0 0</pose>
          <geometry>
            <mesh>
              <scale>1 1 1</scale>
              <uri>/opt/ros/melodic/share/thorvald_description/meshes/clamps/DUMMY-T-BRACKET.stl</uri>
            </mesh>
          </geometry>
        </visual>
        <visual name='base_link_fixed_joint_lump__corner2_3_visual_19'>
          <pose frame=''>0.468 0.75 0.60721 0 0.25 0</pose>
          <geometry>
            <mesh>
              <scale>1 1 1</scale>
              <uri>/opt/ros/melodic/share/thorvald_description/meshes/clamps/DUMMY-SUSP.stl</uri>
            </mesh>
          </geometry>
        </visual>
        <visual name='base_link_fixed_joint_lump__corner2_4_visual_20'>
          <pose frame=''>0.468 0.75 0.75721 0 0.25 0</pose>
          <geometry>
            <mesh>
              <scale>1 1 1</scale>
              <uri>/opt/ros/melodic/share/thorvald_description/meshes/clamps/DUMMY-SUSP.stl</uri>
            </mesh>
          </geometry>
        </visual>
        <visual name='base_link_fixed_joint_lump__corner3_visual_21'>
          <pose frame=''>-0.368 0.75 0.68221 0 -0 3.14159</pose>
          <geometry>
            <cylinder>
              <length>0.15</length>
              <radius>0.02</radius>
            </cylinder>
          </geometry>
        </visual>
        <visual name='base_link_fixed_joint_lump__corner3_1_visual_22'>
          <pose frame=''>-0.425 0.75 0.60721 0 -0 3.14159</pose>
          <geometry>
            <mesh>
              <scale>1 1 1</scale>
              <uri>/opt/ros/melodic/share/thorvald_description/meshes/clamps/DUMMY-T-BRACKET.stl</uri>
            </mesh>
          </geometry>
        </visual>
        <visual name='base_link_fixed_joint_lump__corner3_2_visual_23'>
          <pose frame=''>-0.425 0.75 0.75721 0 -0 3.14159</pose>
          <geometry>
            <mesh>
              <scale>1 1 1</scale>
              <uri>/opt/ros/melodic/share/thorvald_description/meshes/clamps/DUMMY-T-BRACKET.stl</uri>
            </mesh>
          </geometry>
        </visual>
        <visual name='base_link_fixed_joint_lump__corner3_3_visual_24'>
          <pose frame=''>-0.468 0.75 0.60721 0 0.25 3.14159</pose>
          <geometry>
            <mesh>
              <scale>1 1 1</scale>
              <uri>/opt/ros/melodic/share/thorvald_description/meshes/clamps/DUMMY-SUSP.stl</uri>
            </mesh>
          </geometry>
        </visual>
        <visual name='base_link_fixed_joint_lump__corner3_4_visual_25'>
          <pose frame=''>-0.468 0.75 0.75721 0 0.25 3.14159</pose>
          <geometry>
            <mesh>
              <scale>1 1 1</scale>
              <uri>/opt/ros/melodic/share/thorvald_description/meshes/clamps/DUMMY-SUSP.stl</uri>
            </mesh>
          </geometry>
        </visual>
        <visual name='base_link_fixed_joint_lump__pipe0_1_visual_26'>
          <pose frame=''>0 -0.75 0.60721 1.5708 0 -1.5708</pose>
          <geometry>
            <cylinder>
              <length>0.85</length>
              <radius>0.02</radius>
            </cylinder>
          </geometry>
        </visual>
        <visual name='base_link_fixed_joint_lump__pipe0_2_visual_27'>
          <pose frame=''>0 -0.75 0.75721 1.5708 0 -1.5708</pose>
          <geometry>
            <cylinder>
              <length>0.85</length>
              <radius>0.02</radius>
            </cylinder>
          </geometry>
        </visual>
        <visual name='base_link_fixed_joint_lump__pipe1_1_visual_28'>
          <pose frame=''>0.425 0 0.60721 1.5708 -0 0</pose>
          <geometry>
            <cylinder>
              <length>1.5</length>
              <radius>0.02</radius>
            </cylinder>
          </geometry>
        </visual>
        <visual name='base_link_fixed_joint_lump__pipe1_2_visual_29'>
          <pose frame=''>0.425 0 0.75721 1.5708 -0 0</pose>
          <geometry>
            <cylinder>
              <length>1.5</length>
              <radius>0.02</radius>
            </cylinder>
          </geometry>
        </visual>
        <visual name='base_link_fixed_joint_lump__pipe2_1_visual_30'>
          <pose frame=''>0 0.75 0.60721 1.5708 -0 1.5708</pose>
          <geometry>
            <cylinder>
              <length>0.85</length>
              <radius>0.02</radius>
            </cylinder>
          </geometry>
        </visual>
        <visual name='base_link_fixed_joint_lump__pipe2_2_visual_31'>
          <pose frame=''>0 0.75 0.75721 1.5708 -0 1.5708</pose>
          <geometry>
            <cylinder>
              <length>0.85</length>
              <radius>0.02</radius>
            </cylinder>
          </geometry>
        </visual>
        <visual name='base_link_fixed_joint_lump__pipe3_1_visual_32'>
          <pose frame=''>-0.425 0 0.60721 1.5708 -0 3.14159</pose>
          <geometry>
            <cylinder>
              <length>1.5</length>
              <radius>0.02</radius>
            </cylinder>
          </geometry>
        </visual>
        <visual name='base_link_fixed_joint_lump__pipe3_2_visual_33'>
          <pose frame=''>-0.425 0 0.75721 1.5708 -0 3.14159</pose>
          <geometry>
            <cylinder>
              <length>1.5</length>
              <radius>0.02</radius>
            </cylinder>
          </geometry>
        </visual>
        <visual name='base_link_fixed_joint_lump__pipe4_1_visual_34'>
          <pose frame=''>0 0 0.60721 1.5708 -0 -0.515549</pose>
          <geometry>
            <cylinder>
              <length>1.72409</length>
              <radius>0.02</radius>
            </cylinder>
          </geometry>
        </visual>
        <visual name='base_link_fixed_joint_lump__pipe4_2_visual_35'>
          <pose frame=''>0 0 0.75721 1.5708 -0 -0.515549</pose>
          <geometry>
            <cylinder>
              <length>1.72409</length>
              <radius>0.02</radius>
            </cylinder>
          </geometry>
        </visual>
        <self_collide>0</self_collide>
        <enable_wind>0</enable_wind>
        <kinematic>0</kinematic>
      </link>
      <link name='leg0'>
        <pose frame=''>-0.67792 -0.75 0.2 0 -0 0</pose>
        <inertial>
          <pose frame=''>0 0 0 0 -0 0</pose>
          <mass>15.64</mass>
          <inertia>
            <ixx>0.035581</ixx>
            <ixy>0</ixy>
            <ixz>0</ixz>
            <iyy>0.035581</iyy>
            <iyz>0</iyz>
            <izz>0.012512</izz>
          </inertia>
        </inertial>
        <collision name='leg0_collision'>
          <pose frame=''>0 0 0 0 -0 -3.14159</pose>
          <geometry>
            <mesh>
              <scale>1 1 1</scale>
              <uri>/opt/ros/melodic/share/thorvald_description/meshes/drive_modules/836745-5-DUMMY-RevA.stl</uri>
            </mesh>
          </geometry>
          <max_contacts>10</max_contacts>
          <surface>
            <contact>
              <ode/>
            </contact>
            <bounce/>
            <friction>
              <torsional>
                <ode/>
              </torsional>
              <ode/>
            </friction>
          </surface>
        </collision>
        <visual name='leg0_visual'>
          <pose frame=''>0 0 0 0 -0 -3.14159</pose>
          <geometry>
            <mesh>
              <scale>1 1 1</scale>
              <uri>/opt/ros/melodic/share/thorvald_description/meshes/drive_modules/836745-5-DUMMY-RevA.stl</uri>
            </mesh>
          </geometry>
        </visual>
        <self_collide>0</self_collide>
        <enable_wind>0</enable_wind>
        <kinematic>0</kinematic>
      </link>
      <joint name='steering0' type='revolute'>
        <child>leg0</child>
        <parent>base_link</parent>
        <axis>
          <xyz>0 0 1</xyz>
          <limit>
            <lower>-1e+16</lower>
            <upper>1e+16</upper>
          </limit>
          <dynamics>
            <damping>100</damping>
            <friction>10000</friction>
            <spring_reference>0</spring_reference>
            <spring_stiffness>0</spring_stiffness>
          </dynamics>
          <use_parent_model_frame>1</use_parent_model_frame>
        </axis>
      </joint>
      <link name='wheel0_link'>
        <pose frame=''>-0.67792 -0.75 0.2 -1.5708 0 0</pose>
        <inertial>
          <pose frame=''>0 0 0 0 -0 0</pose>
          <mass>6</mass>
          <inertia>
            <ixx>0.0728</ixx>
            <ixy>0</ixy>
            <ixz>0</ixz>
            <iyy>0.0728</iyy>
            <iyz>0</iyz>
            <izz>0.12</izz>
          </inertia>
        </inertial>
        <collision name='wheel0_link_collision'>
          <pose frame=''>0 0 0 0 -0 0</pose>
          <geometry>
            <cylinder>
              <length>0.16</length>
              <radius>0.2</radius>
            </cylinder>
          </geometry>
          <surface>
            <contact>
              <ode/>
            </contact>
            <friction>
              <ode>
                <mu>2</mu>
                <mu2>2</mu2>
              </ode>
              <torsional>
                <ode/>
              </torsional>
            </friction>
            <bounce/>
          </surface>
          <max_contacts>10</max_contacts>
        </collision>
        <visual name='wheel0_link_visual'>
          <pose frame=''>0 0 0 0 -0 0</pose>
          <geometry>
            <cylinder>
              <length>0.16</length>
              <radius>0.2</radius>
            </cylinder>
          </geometry>
          <material>
            <script>
              <name>Gazebo/Black</name>
              <uri>file://media/materials/scripts/gazebo.material</uri>
            </script>
          </material>
        </visual>
        <gravity>1</gravity>
        <velocity_decay/>
        <self_collide>0</self_collide>
        <enable_wind>0</enable_wind>
        <kinematic>0</kinematic>
      </link>
      <joint name='wheel0' type='revolute'>
        <child>wheel0_link</child>
        <parent>leg0</parent>
        <axis>
          <xyz>0 1 0</xyz>
          <limit>
            <lower>-1e+16</lower>
            <upper>1e+16</upper>
          </limit>
          <dynamics>
            <damping>100</damping>
            <friction>1000</friction>
            <spring_reference>0</spring_reference>
            <spring_stiffness>0</spring_stiffness>
          </dynamics>
          <use_parent_model_frame>1</use_parent_model_frame>
        </axis>
      </joint>
      <link name='leg1'>
        <pose frame=''>0.67792 -0.75 0.2 0 -0 0</pose>
        <inertial>
          <pose frame=''>0 0 0 0 -0 0</pose>
          <mass>15.64</mass>
          <inertia>
            <ixx>0.035581</ixx>
            <ixy>0</ixy>
            <ixz>0</ixz>
            <iyy>0.035581</iyy>
            <iyz>0</iyz>
            <izz>0.012512</izz>
          </inertia>
        </inertial>
        <collision name='leg1_collision'>
          <pose frame=''>0 0 0 0 -0 0</pose>
          <geometry>
            <mesh>
              <scale>1 1 1</scale>
              <uri>/opt/ros/melodic/share/thorvald_description/meshes/drive_modules/836745-5-DUMMY-MIRROR-RevA.stl</uri>
            </mesh>
          </geometry>
          <max_contacts>10</max_contacts>
          <surface>
            <contact>
              <ode/>
            </contact>
            <bounce/>
            <friction>
              <torsional>
                <ode/>
              </torsional>
              <ode/>
            </friction>
          </surface>
        </collision>
        <visual name='leg1_visual'>
          <pose frame=''>0 0 0 0 -0 0</pose>
          <geometry>
            <mesh>
              <scale>1 1 1</scale>
              <uri>/opt/ros/melodic/share/thorvald_description/meshes/drive_modules/836745-5-DUMMY-MIRROR-RevA.stl</uri>
            </mesh>
          </geometry>
        </visual>
        <self_collide>0</self_collide>
        <enable_wind>0</enable_wind>
        <kinematic>0</kinematic>
      </link>
      <joint name='steering1' type='revolute'>
        <child>leg1</child>
        <parent>base_link</parent>
        <axis>
          <xyz>0 0 1</xyz>
          <limit>
            <lower>-1e+16</lower>
            <upper>1e+16</upper>
          </limit>
          <dynamics>
            <damping>100</damping>
            <friction>10000</friction>
            <spring_reference>0</spring_reference>
            <spring_stiffness>0</spring_stiffness>
          </dynamics>
          <use_parent_model_frame>1</use_parent_model_frame>
        </axis>
      </joint>
      <link name='wheel1_link'>
        <pose frame=''>0.67792 -0.75 0.2 -1.5708 0 0</pose>
        <inertial>
          <pose frame=''>0 0 0 0 -0 0</pose>
          <mass>6</mass>
          <inertia>
            <ixx>0.0728</ixx>
            <ixy>0</ixy>
            <ixz>0</ixz>
            <iyy>0.0728</iyy>
            <iyz>0</iyz>
            <izz>0.12</izz>
          </inertia>
        </inertial>
        <collision name='wheel1_link_collision'>
          <pose frame=''>0 0 0 0 -0 0</pose>
          <geometry>
            <cylinder>
              <length>0.16</length>
              <radius>0.2</radius>
            </cylinder>
          </geometry>
          <surface>
            <contact>
              <ode/>
            </contact>
            <friction>
              <ode>
                <mu>2</mu>
                <mu2>2</mu2>
              </ode>
              <torsional>
                <ode/>
              </torsional>
            </friction>
            <bounce/>
          </surface>
          <max_contacts>10</max_contacts>
        </collision>
        <visual name='wheel1_link_visual'>
          <pose frame=''>0 0 0 0 -0 0</pose>
          <geometry>
            <cylinder>
              <length>0.16</length>
              <radius>0.2</radius>
            </cylinder>
          </geometry>
          <material>
            <script>
              <name>Gazebo/Black</name>
              <uri>file://media/materials/scripts/gazebo.material</uri>
            </script>
          </material>
        </visual>
        <gravity>1</gravity>
        <velocity_decay/>
        <self_collide>0</self_collide>
        <enable_wind>0</enable_wind>
        <kinematic>0</kinematic>
      </link>
      <joint name='wheel1' type='revolute'>
        <child>wheel1_link</child>
        <parent>leg1</parent>
        <axis>
          <xyz>0 1 0</xyz>
          <limit>
            <lower>-1e+16</lower>
            <upper>1e+16</upper>
          </limit>
          <dynamics>
            <damping>100</damping>
            <friction>1000</friction>
            <spring_reference>0</spring_reference>
            <spring_stiffness>0</spring_stiffness>
          </dynamics>
          <use_parent_model_frame>1</use_parent_model_frame>
        </axis>
      </joint>
      <link name='leg2'>
        <pose frame=''>0.67792 0.75 0.2 0 -0 0</pose>
        <inertial>
          <pose frame=''>0 0 0 0 -0 0</pose>
          <mass>15.64</mass>
          <inertia>
            <ixx>0.035581</ixx>
            <ixy>0</ixy>
            <ixz>0</ixz>
            <iyy>0.035581</iyy>
            <iyz>0</iyz>
            <izz>0.012512</izz>
          </inertia>
        </inertial>
        <collision name='leg2_collision'>
          <pose frame=''>0 0 0 0 -0 0</pose>
          <geometry>
            <mesh>
              <scale>1 1 1</scale>
              <uri>/opt/ros/melodic/share/thorvald_description/meshes/drive_modules/836745-5-DUMMY-RevA.stl</uri>
            </mesh>
          </geometry>
          <max_contacts>10</max_contacts>
          <surface>
            <contact>
              <ode/>
            </contact>
            <bounce/>
            <friction>
              <torsional>
                <ode/>
              </torsional>
              <ode/>
            </friction>
          </surface>
        </collision>
        <visual name='leg2_visual'>
          <pose frame=''>0 0 0 0 -0 0</pose>
          <geometry>
            <mesh>
              <scale>1 1 1</scale>
              <uri>/opt/ros/melodic/share/thorvald_description/meshes/drive_modules/836745-5-DUMMY-RevA.stl</uri>
            </mesh>
          </geometry>
        </visual>
        <self_collide>0</self_collide>
        <enable_wind>0</enable_wind>
        <kinematic>0</kinematic>
      </link>
      <joint name='steering2' type='revolute'>
        <child>leg2</child>
        <parent>base_link</parent>
        <axis>
          <xyz>0 0 1</xyz>
          <limit>
            <lower>-1e+16</lower>
            <upper>1e+16</upper>
          </limit>
          <dynamics>
            <damping>100</damping>
            <friction>10000</friction>
            <spring_reference>0</spring_reference>
            <spring_stiffness>0</spring_stiffness>
          </dynamics>
          <use_parent_model_frame>1</use_parent_model_frame>
        </axis>
      </joint>
      <link name='wheel2_link'>
        <pose frame=''>0.67792 0.75 0.2 -1.5708 0 0</pose>
        <inertial>
          <pose frame=''>0 0 0 0 -0 0</pose>
          <mass>6</mass>
          <inertia>
            <ixx>0.0728</ixx>
            <ixy>0</ixy>
            <ixz>0</ixz>
            <iyy>0.0728</iyy>
            <iyz>0</iyz>
            <izz>0.12</izz>
          </inertia>
        </inertial>
        <collision name='wheel2_link_collision'>
          <pose frame=''>0 0 0 0 -0 0</pose>
          <geometry>
            <cylinder>
              <length>0.16</length>
              <radius>0.2</radius>
            </cylinder>
          </geometry>
          <surface>
            <contact>
              <ode/>
            </contact>
            <friction>
              <ode>
                <mu>2</mu>
                <mu2>2</mu2>
              </ode>
              <torsional>
                <ode/>
              </torsional>
            </friction>
            <bounce/>
          </surface>
          <max_contacts>10</max_contacts>
        </collision>
        <visual name='wheel2_link_visual'>
          <pose frame=''>0 0 0 0 -0 0</pose>
          <geometry>
            <cylinder>
              <length>0.16</length>
              <radius>0.2</radius>
            </cylinder>
          </geometry>
          <material>
            <script>
              <name>Gazebo/Black</name>
              <uri>file://media/materials/scripts/gazebo.material</uri>
            </script>
          </material>
        </visual>
        <gravity>1</gravity>
        <velocity_decay/>
        <self_collide>0</self_collide>
        <enable_wind>0</enable_wind>
        <kinematic>0</kinematic>
      </link>
      <joint name='wheel2' type='revolute'>
        <child>wheel2_link</child>
        <parent>leg2</parent>
        <axis>
          <xyz>0 1 0</xyz>
          <limit>
            <lower>-1e+16</lower>
            <upper>1e+16</upper>
          </limit>
          <dynamics>
            <damping>100</damping>
            <friction>1000</friction>
            <spring_reference>0</spring_reference>
            <spring_stiffness>0</spring_stiffness>
          </dynamics>
          <use_parent_model_frame>1</use_parent_model_frame>
        </axis>
      </joint>
      <link name='leg3'>
        <pose frame=''>-0.67792 0.75 0.2 0 -0 0</pose>
        <inertial>
          <pose frame=''>0 0 0 0 -0 0</pose>
          <mass>15.64</mass>
          <inertia>
            <ixx>0.035581</ixx>
            <ixy>0</ixy>
            <ixz>0</ixz>
            <iyy>0.035581</iyy>
            <iyz>0</iyz>
            <izz>0.012512</izz>
          </inertia>
        </inertial>
        <collision name='leg3_collision'>
          <pose frame=''>0 0 0 0 -0 -3.14159</pose>
          <geometry>
            <mesh>
              <scale>1 1 1</scale>
              <uri>/opt/ros/melodic/share/thorvald_description/meshes/drive_modules/836745-5-DUMMY-MIRROR-RevA.stl</uri>
            </mesh>
          </geometry>
          <max_contacts>10</max_contacts>
          <surface>
            <contact>
              <ode/>
            </contact>
            <bounce/>
            <friction>
              <torsional>
                <ode/>
              </torsional>
              <ode/>
            </friction>
          </surface>
        </collision>
        <visual name='leg3_visual'>
          <pose frame=''>0 0 0 0 -0 -3.14159</pose>
          <geometry>
            <mesh>
              <scale>1 1 1</scale>
              <uri>/opt/ros/melodic/share/thorvald_description/meshes/drive_modules/836745-5-DUMMY-MIRROR-RevA.stl</uri>
            </mesh>
          </geometry>
        </visual>
        <self_collide>0</self_collide>
        <enable_wind>0</enable_wind>
        <kinematic>0</kinematic>
      </link>
      <joint name='steering3' type='revolute'>
        <child>leg3</child>
        <parent>base_link</parent>
        <axis>
          <xyz>0 0 1</xyz>
          <limit>
            <lower>-1e+16</lower>
            <upper>1e+16</upper>
          </limit>
          <dynamics>
            <damping>100</damping>
            <friction>10000</friction>
            <spring_reference>0</spring_reference>
            <spring_stiffness>0</spring_stiffness>
          </dynamics>
          <use_parent_model_frame>1</use_parent_model_frame>
        </axis>
      </joint>
      <link name='wheel3_link'>
        <pose frame=''>-0.67792 0.75 0.2 -1.5708 0 0</pose>
        <inertial>
          <pose frame=''>0 0 0 0 -0 0</pose>
          <mass>6</mass>
          <inertia>
            <ixx>0.0728</ixx>
            <ixy>0</ixy>
            <ixz>0</ixz>
            <iyy>0.0728</iyy>
            <iyz>0</iyz>
            <izz>0.12</izz>
          </inertia>
        </inertial>
        <collision name='wheel3_link_collision'>
          <pose frame=''>0 0 0 0 -0 0</pose>
          <geometry>
            <cylinder>
              <length>0.16</length>
              <radius>0.2</radius>
            </cylinder>
          </geometry>
          <surface>
            <contact>
              <ode/>
            </contact>
            <friction>
              <ode>
                <mu>2</mu>
                <mu2>2</mu2>
              </ode>
              <torsional>
                <ode/>
              </torsional>
            </friction>
            <bounce/>
          </surface>
          <max_contacts>10</max_contacts>
        </collision>
        <visual name='wheel3_link_visual'>
          <pose frame=''>0 0 0 0 -0 0</pose>
          <geometry>
            <cylinder>
              <length>0.16</length>
              <radius>0.2</radius>
            </cylinder>
          </geometry>
          <material>
            <script>
              <name>Gazebo/Black</name>
              <uri>file://media/materials/scripts/gazebo.material</uri>
            </script>
          </material>
        </visual>
        <gravity>1</gravity>
        <velocity_decay/>
        <self_collide>0</self_collide>
        <enable_wind>0</enable_wind>
        <kinematic>0</kinematic>
      </link>
      <joint name='wheel3' type='revolute'>
        <child>wheel3_link</child>
        <parent>leg3</parent>
        <axis>
          <xyz>0 1 0</xyz>
          <limit>
            <lower>-1e+16</lower>
            <upper>1e+16</upper>
          </limit>
          <dynamics>
            <damping>100</damping>
            <friction>1000</friction>
            <spring_reference>0</spring_reference>
            <spring_stiffness>0</spring_stiffness>
          </dynamics>
          <use_parent_model_frame>1</use_parent_model_frame>
        </axis>
      </joint>
      <plugin name='_thorvald_gazebo_plugins' filename='libthorvald_gazebo_plugins_synch.so'>
        <alwaysOn>1</alwaysOn>
        <updateRate>20</updateRate>
        <robotNamespace/>
        <commandTopic>base_state</commandTopic>
        <odometryTopic>odometry/gazebo</odometryTopic>
        <odometryFrame>odom</odometryFrame>
        <robotBaseFrame>base_link</robotBaseFrame>
        <steering0>steering0</steering0>
        <steering1>steering1</steering1>
        <steering2>steering2</steering2>
        <steering3>steering3</steering3>
        <steering4>steering4</steering4>
        <steering5>steering5</steering5>
        <steering6>steering6</steering6>
        <steering7>steering7</steering7>
        <steering8>steering8</steering8>
        <steering9>steering9</steering9>
        <steering10>ssteering10</steering10>
        <wheel0>wheel0</wheel0>
        <wheel1>wheel1</wheel1>
        <wheel2>wheel2</wheel2>
        <wheel3>wheel3</wheel3>
        <wheel4>wheel4</wheel4>
        <wheel5>wheel5</wheel5>
        <wheel6>wheel6</wheel6>
        <wheel7>wheel7</wheel7>
        <wheel8>wheel8</wheel8>
        <wheel9>wheel9</wheel9>
        <wheel10>wheel10</wheel10>
      </plugin>
      <static>0</static>
      <plugin name='gazebo_ros_control' filename='libgazebo_ros_control.so'>
        <robotNamespace>/thorvald</robotNamespace>
      </plugin>
      <pose frame=''>0 0 1 0 -0 0</pose>
    </model>
    <model name='table'>
      <static>1</static>
      <link name='link'>
        <collision name='surface'>
          <pose frame=''>0 0 1 0 -0 0</pose>
          <geometry>
            <box>
              <size>1.5 0.8 0.03</size>
            </box>
          </geometry>
          <surface>
            <friction>
              <ode>
                <mu>0.6</mu>
                <mu2>0.6</mu2>
              </ode>
              <torsional>
                <ode/>
              </torsional>
            </friction>
            <contact>
              <ode/>
            </contact>
            <bounce/>
          </surface>
          <max_contacts>10</max_contacts>
        </collision>
        <visual name='visual1'>
          <pose frame=''>0 0 1 0 -0 0</pose>
          <geometry>
            <box>
              <size>1.5 0.8 0.03</size>
            </box>
          </geometry>
          <material>
            <script>
              <uri>file://media/materials/scripts/gazebo.material</uri>
              <name>Gazebo/Wood</name>
            </script>
          </material>
        </visual>
        <collision name='front_left_leg'>
          <pose frame=''>0.68 0.38 0.5 0 -0 0</pose>
          <geometry>
            <cylinder>
              <radius>0.02</radius>
              <length>1</length>
            </cylinder>
          </geometry>
          <max_contacts>10</max_contacts>
          <surface>
            <contact>
              <ode/>
            </contact>
            <bounce/>
            <friction>
              <torsional>
                <ode/>
              </torsional>
              <ode/>
            </friction>
          </surface>
        </collision>
        <visual name='front_left_leg'>
          <pose frame=''>0.68 0.38 0.5 0 -0 0</pose>
          <geometry>
            <cylinder>
              <radius>0.02</radius>
              <length>1</length>
            </cylinder>
          </geometry>
          <material>
            <script>
              <uri>file://media/materials/scripts/gazebo.material</uri>
              <name>Gazebo/Grey</name>
            </script>
          </material>
        </visual>
        <collision name='front_right_leg'>
          <pose frame=''>0.68 -0.38 0.5 0 -0 0</pose>
          <geometry>
            <cylinder>
              <radius>0.02</radius>
              <length>1</length>
            </cylinder>
          </geometry>
          <max_contacts>10</max_contacts>
          <surface>
            <contact>
              <ode/>
            </contact>
            <bounce/>
            <friction>
              <torsional>
                <ode/>
              </torsional>
              <ode/>
            </friction>
          </surface>
        </collision>
        <visual name='front_right_leg'>
          <pose frame=''>0.68 -0.38 0.5 0 -0 0</pose>
          <geometry>
            <cylinder>
              <radius>0.02</radius>
              <length>1</length>
            </cylinder>
          </geometry>
          <material>
            <script>
              <uri>file://media/materials/scripts/gazebo.material</uri>
              <name>Gazebo/Grey</name>
            </script>
          </material>
        </visual>
        <collision name='back_right_leg'>
          <pose frame=''>-0.68 -0.38 0.5 0 -0 0</pose>
          <geometry>
            <cylinder>
              <radius>0.02</radius>
              <length>1</length>
            </cylinder>
          </geometry>
          <max_contacts>10</max_contacts>
          <surface>
            <contact>
              <ode/>
            </contact>
            <bounce/>
            <friction>
              <torsional>
                <ode/>
              </torsional>
              <ode/>
            </friction>
          </surface>
        </collision>
        <visual name='back_right_leg'>
          <pose frame=''>-0.68 -0.38 0.5 0 -0 0</pose>
          <geometry>
            <cylinder>
              <radius>0.02</radius>
              <length>1</length>
            </cylinder>
          </geometry>
          <material>
            <script>
              <uri>file://media/materials/scripts/gazebo.material</uri>
              <name>Gazebo/Grey</name>
            </script>
          </material>
        </visual>
        <collision name='back_left_leg'>
          <pose frame=''>-0.68 0.38 0.5 0 -0 0</pose>
          <geometry>
            <cylinder>
              <radius>0.02</radius>
              <length>1</length>
            </cylinder>
          </geometry>
          <max_contacts>10</max_contacts>
          <surface>
            <contact>
              <ode/>
            </contact>
            <bounce/>
            <friction>
              <torsional>
                <ode/>
              </torsional>
              <ode/>
            </friction>
          </surface>
        </collision>
        <visual name='back_left_leg'>
          <pose frame=''>-0.68 0.38 0.5 0 -0 0</pose>
          <geometry>
            <cylinder>
              <radius>0.02</radius>
              <length>1</length>
            </cylinder>
          </geometry>
          <material>
            <script>
              <uri>file://media/materials/scripts/gazebo.material</uri>
              <name>Gazebo/Grey</name>
            </script>
          </material>
        </visual>
        <self_collide>0</self_collide>
        <enable_wind>0</enable_wind>
        <kinematic>0</kinematic>
      </link>
      <pose frame=''>7.10828 -0.654531 0 0 -0 0</pose>
    </model>
    <model name='cafe_table'>
      <static>1</static>
      <link name='link'>
        <collision name='surface'>
          <pose frame=''>0 0 0.755 0 -0 0</pose>
          <geometry>
            <box>
              <size>0.913 0.913 0.04</size>
            </box>
          </geometry>
          <max_contacts>10</max_contacts>
          <surface>
            <contact>
              <ode/>
            </contact>
            <bounce/>
            <friction>
              <torsional>
                <ode/>
              </torsional>
              <ode/>
            </friction>
          </surface>
        </collision>
        <collision name='column'>
          <pose frame=''>0 0 0.37 0 -0 0</pose>
          <geometry>
            <box>
              <size>0.042 0.042 0.74</size>
            </box>
          </geometry>
          <max_contacts>10</max_contacts>
          <surface>
            <contact>
              <ode/>
            </contact>
            <bounce/>
            <friction>
              <torsional>
                <ode/>
              </torsional>
              <ode/>
            </friction>
          </surface>
        </collision>
        <collision name='base'>
          <pose frame=''>0 0 0.02 0 -0 0</pose>
          <geometry>
            <box>
              <size>0.56 0.56 0.04</size>
            </box>
          </geometry>
          <max_contacts>10</max_contacts>
          <surface>
            <contact>
              <ode/>
            </contact>
            <bounce/>
            <friction>
              <torsional>
                <ode/>
              </torsional>
              <ode/>
            </friction>
          </surface>
        </collision>
        <visual name='visual'>
          <geometry>
            <mesh>
              <uri>model://cafe_table/meshes/cafe_table.dae</uri>
            </mesh>
          </geometry>
        </visual>
        <self_collide>0</self_collide>
        <enable_wind>0</enable_wind>
        <kinematic>0</kinematic>
      </link>
      <pose frame=''>6.09954 -4.74777 0 0 -0 0</pose>
    </model>
    <model name='cabinet'>
      <static>1</static>
      <link name='cabinet_bottom_plate'>
        <inertial>
          <pose frame=''>0 0 -1 0 -0 0</pose>
          <inertia>
            <ixx>2.05</ixx>
            <ixy>0</ixy>
            <ixz>0</ixz>
            <iyy>2.05</iyy>
            <iyz>0</iyz>
            <izz>2.05</izz>
          </inertia>
          <mass>25</mass>
        </inertial>
        <collision name='cabinet_bottom_plate_geom'>
          <pose frame=''>0 0 0.01 0 -0 0</pose>
          <geometry>
            <box>
              <size>0.45 0.45 0.02</size>
            </box>
          </geometry>
          <max_contacts>10</max_contacts>
          <surface>
            <contact>
              <ode/>
            </contact>
            <bounce/>
            <friction>
              <torsional>
                <ode/>
              </torsional>
              <ode/>
            </friction>
          </surface>
        </collision>
        <visual name='cabinet_bottom_plate_geom_visual'>
          <pose frame=''>0 0 0.01 0 -0 0</pose>
          <geometry>
            <box>
              <size>0.45 0.45 0.02</size>
            </box>
          </geometry>
          <material>
            <script>
              <uri>file://media/materials/scripts/gazebo.material</uri>
              <name>Gazebo/Wood</name>
            </script>
          </material>
        </visual>
        <collision name='cabinet_bottom_plate_geom_cabinet_back_plate'>
          <pose frame=''>0.235 0 0.51 0 -0 0</pose>
          <geometry>
            <box>
              <size>0.02 0.45 1.02</size>
            </box>
          </geometry>
          <max_contacts>10</max_contacts>
          <surface>
            <contact>
              <ode/>
            </contact>
            <bounce/>
            <friction>
              <torsional>
                <ode/>
              </torsional>
              <ode/>
            </friction>
          </surface>
        </collision>
        <visual name='cabinet_bottom_plate_geom_cabinet_back_plate_visual'>
          <pose frame=''>0.235 0 0.51 0 -0 0</pose>
          <geometry>
            <box>
              <size>0.02 0.45 1.02</size>
            </box>
          </geometry>
          <material>
            <script>
              <uri>file://media/materials/scripts/gazebo.material</uri>
              <name>Gazebo/Wood</name>
            </script>
          </material>
        </visual>
        <collision name='cabinet_bottom_plate_geom_cabinet_left_plate'>
          <pose frame=''>0 0.235 0.51 0 -0 0</pose>
          <geometry>
            <box>
              <size>0.45 0.02 1.02</size>
            </box>
          </geometry>
          <max_contacts>10</max_contacts>
          <surface>
            <contact>
              <ode/>
            </contact>
            <bounce/>
            <friction>
              <torsional>
                <ode/>
              </torsional>
              <ode/>
            </friction>
          </surface>
        </collision>
        <visual name='cabinet_bottom_plate_geom_cabinet_left_plate_visual'>
          <pose frame=''>0 0.235 0.51 0 -0 0</pose>
          <geometry>
            <box>
              <size>0.45 0.02 1.02</size>
            </box>
          </geometry>
          <material>
            <script>
              <uri>file://media/materials/scripts/gazebo.material</uri>
              <name>Gazebo/Wood</name>
            </script>
          </material>
        </visual>
        <collision name='cabinet_bottom_plate_geom_cabinet_middle_plate'>
          <pose frame=''>0 0 0.51 0 -0 0</pose>
          <geometry>
            <box>
              <size>0.45 0.45 0.02</size>
            </box>
          </geometry>
          <max_contacts>10</max_contacts>
          <surface>
            <contact>
              <ode/>
            </contact>
            <bounce/>
            <friction>
              <torsional>
                <ode/>
              </torsional>
              <ode/>
            </friction>
          </surface>
        </collision>
        <visual name='cabinet_bottom_plate_geom_cabinet_middle_plate_visual'>
          <pose frame=''>0 0 0.51 0 -0 0</pose>
          <geometry>
            <box>
              <size>0.45 0.45 0.02</size>
            </box>
          </geometry>
          <material>
            <script>
              <uri>file://media/materials/scripts/gazebo.material</uri>
              <name>Gazebo/Wood</name>
            </script>
          </material>
        </visual>
        <collision name='cabinet_bottom_plate_geom_cabinet_right_plate'>
          <pose frame=''>0 -0.235 0.51 0 -0 0</pose>
          <geometry>
            <box>
              <size>0.45 0.02 1.02</size>
            </box>
          </geometry>
          <max_contacts>10</max_contacts>
          <surface>
            <contact>
              <ode/>
            </contact>
            <bounce/>
            <friction>
              <torsional>
                <ode/>
              </torsional>
              <ode/>
            </friction>
          </surface>
        </collision>
        <visual name='cabinet_bottom_plate_geom_cabinet_right_plate_visual'>
          <pose frame=''>0 -0.235 0.51 0 -0 0</pose>
          <geometry>
            <box>
              <size>0.45 0.02 1.02</size>
            </box>
          </geometry>
          <material>
            <script>
              <uri>file://media/materials/scripts/gazebo.material</uri>
              <name>Gazebo/Wood</name>
            </script>
          </material>
        </visual>
        <collision name='cabinet_bottom_plate_geom_cabinet_top_plate'>
          <pose frame=''>0 0 1.01 0 -0 0</pose>
          <geometry>
            <box>
              <size>0.45 0.45 0.02</size>
            </box>
          </geometry>
          <max_contacts>10</max_contacts>
          <surface>
            <contact>
              <ode/>
            </contact>
            <bounce/>
            <friction>
              <torsional>
                <ode/>
              </torsional>
              <ode/>
            </friction>
          </surface>
        </collision>
        <visual name='cabinet_bottom_plate_geom_cabinet_top_plate_visual'>
          <pose frame=''>0 0 1.01 0 -0 0</pose>
          <geometry>
            <box>
              <size>0.45 0.45 0.02</size>
            </box>
          </geometry>
          <material>
            <script>
              <uri>file://media/materials/scripts/gazebo.material</uri>
              <name>Gazebo/Wood</name>
            </script>
          </material>
        </visual>
        <self_collide>0</self_collide>
        <enable_wind>0</enable_wind>
        <kinematic>0</kinematic>
      </link>
      <pose frame=''>1.46103 4.4242 0 0 -0 0</pose>
    </model>
    <state world_name='default'>
      <sim_time>344 394000000</sim_time>
      <real_time>356 830676521</real_time>
      <wall_time>1633507866 928249078</wall_time>
      <iterations>344394</iterations>
      <model name='cabinet'>
        <pose frame=''>1.46103 4.4242 0 0 -0 0</pose>
        <scale>1 1 1</scale>
        <link name='cabinet_bottom_plate'>
          <pose frame=''>1.46103 4.4242 0 0 -0 0</pose>
          <velocity>0 0 0 0 -0 0</velocity>
          <acceleration>0 0 0 0 -0 0</acceleration>
          <wrench>0 0 0 0 -0 0</wrench>
        </link>
      </model>
      <model name='cafe_table'>
        <pose frame=''>6.09954 -4.74777 0 0 -0 0</pose>
        <scale>1 1 1</scale>
        <link name='link'>
          <pose frame=''>6.09954 -4.74777 0 0 -0 0</pose>
          <velocity>0 0 0 0 -0 0</velocity>
          <acceleration>0 0 0 0 -0 0</acceleration>
          <wrench>0 0 0 0 -0 0</wrench>
        </link>
      </model>
      <model name='ground_plane'>
        <pose frame=''>0 0 0 0 -0 0</pose>
        <scale>1 1 1</scale>
        <link name='link'>
          <pose frame=''>0 0 0 0 -0 0</pose>
          <velocity>0 0 0 0 -0 0</velocity>
          <acceleration>0 0 0 0 -0 0</acceleration>
          <wrench>0 0 0 0 -0 0</wrench>
        </link>
      </model>
      <model name='robot'>
        <pose frame=''>0.004062 -0.00071 1e-06 0 -0 8.6e-05</pose>
        <scale>1 1 1</scale>
        <link name='base_link'>
          <pose frame=''>0.004062 -0.00071 1e-06 0 -0 8.6e-05</pose>
          <velocity>2.1e-05 -0 -3e-06 0 -0 0</velocity>
          <acceleration>-1.1e-05 -3.3e-05 0 -1.7e-05 -1e-06 8e-06</acceleration>
          <wrench>-0.001012 -0.00309 1.2e-05 0 -0 0</wrench>
        </link>
        <link name='leg0'>
          <pose frame=''>-0.673794 -0.750768 0.200001 7e-06 0 -0.012908</pose>
          <velocity>2.1e-05 -1e-06 -3e-06 -1.9e-05 1e-06 -9.4e-05</velocity>
          <acceleration>-3e-06 -3.7e-05 1.1e-05 -0.000156 0.000382 7.1e-05</acceleration>
          <wrench>-3.9e-05 -0.000578 0.000179 0 -0 0</wrench>
        </link>
        <link name='leg1'>
          <pose frame=''>0.682046 -0.750651 0.200001 7e-06 -0 -0.017131</pose>
          <velocity>2.2e-05 -0 -3e-06 -2e-05 -1e-06 -9.2e-05</velocity>
          <acceleration>-6e-06 -2.9e-05 1.2e-05 -0.000136 0.000706 0.000666</acceleration>
          <wrench>-9e-05 -0.000447 0.00019 0 -0 0</wrench>
        </link>
        <link name='leg2'>
          <pose frame=''>0.681917 0.749348 0.200001 -6e-06 -0 0.018367</pose>
          <velocity>2.1e-05 0 -3e-06 1.9e-05 -1e-06 9.3e-05</velocity>
          <acceleration>-1.8e-05 -4.4e-05 -1.5e-05 0.000295 0.000671 -0.000746</acceleration>
          <wrench>-0.000276 -0.000695 -0.000231 0 -0 0</wrench>
        </link>
        <link name='leg3'>
          <pose frame=''>-0.673923 0.749232 0.200001 2e-06 -0 -0.002196</pose>
          <velocity>2.1e-05 -0 -3e-06 -6e-06 -0 -1.4e-05</velocity>
          <acceleration>-1.6e-05 -4.5e-05 -1.4e-05 -0.000106 4.9e-05 0.000163</acceleration>
          <wrench>-0.000252 -0.000706 -0.000213 0 -0 0</wrench>
        </link>
        <link name='wheel0_link'>
          <pose frame=''>-0.673794 -0.750767 0.200001 -1.57078 0.005986 -0.012908</pose>
          <velocity>2.1e-05 -3e-06 -3e-06 -5e-05 6.7e-05 -9.4e-05</velocity>
          <acceleration>9e-06 1e-06 1e-05 3.11613 -1.15861 3.14145</acceleration>
          <wrench>5.4e-05 4e-06 6e-05 0 -0 0</wrench>
        </link>
        <link name='wheel1_link'>
          <pose frame=''>0.682046 -0.75065 0.200001 -1.57078 0.014632 -0.017131</pose>
          <velocity>2.2e-05 -3e-06 -3e-06 -4.9e-05 6.9e-05 -9.2e-05</velocity>
          <acceleration>-1.4e-05 5e-06 9e-06 -0.082432 1.46527 0.000286</acceleration>
          <wrench>-8.5e-05 2.9e-05 5.3e-05 0 -0 0</wrench>
        </link>
        <link name='wheel2_link'>
          <pose frame=''>0.681917 0.749347 0.200002 -1.57082 0.017307 0.018367</pose>
          <velocity>2.2e-05 2e-06 -3e-06 4.9e-05 6.9e-05 9.2e-05</velocity>
          <acceleration>-2.7e-05 -6.7e-05 -1.8e-05 0.104793 0.588672 -0.000324</acceleration>
          <wrench>-0.000164 -0.000403 -0.000109 0 -0 0</wrench>
        </link>
        <link name='wheel3_link'>
          <pose frame=''>-0.673923 0.749231 0.200002 -1.57082 0.013955 -0.002196</pose>
          <velocity>2.1e-05 2e-06 -3e-06 4.9e-05 0.000111 -1.3e-05</velocity>
          <acceleration>-6e-06 -7.4e-05 -2.1e-05 3.13171 1.46874 3.1413</acceleration>
          <wrench>-3.8e-05 -0.000445 -0.000126 0 -0 0</wrench>
        </link>
      </model>
      <model name='table'>
        <pose frame=''>7.10828 -0.654531 0 0 -0 0</pose>
        <scale>1 1 1</scale>
        <link name='link'>
          <pose frame=''>7.10828 -0.654531 0 0 -0 0</pose>
          <velocity>0 0 0 0 -0 0</velocity>
          <acceleration>0 0 0 0 -0 0</acceleration>
          <wrench>0 0 0 0 -0 0</wrench>
        </link>
      </model>
      <light name='sun'>
        <pose frame=''>0 0 10 0 -0 0</pose>
      </light>
    </state>
    <gui fullscreen='0'>
      <camera name='user_camera'>
        <pose frame=''>17.3466 -9.79262 4.14898 0 0.275643 2.3562</pose>
        <view_controller>orbit</view_controller>
        <projection_type>perspective</projection_type>
      </camera>
    </gui>
  </world>
</sdf>
